File: imap_versions/other_machine_outputs_examples/Invar_LT_05_01.TRA
"Specimen thickness",1.5,"mm"
"Specimen width",4.89,"mm"
"Cross-section",7.335,"mm²"
"Gage length, standard travel",30,"mm"
"Extensometer",""
"Load cell",""
"Date/Clock time",44182.5,""
"Operator",""
"v1",1,"mm/min"
"v2",1,"mm/min"
"Time","Crosshead absolute","Standard travel","Standard force","Capteur de course"
"s","mm","mm","N","mm"
2.63805,1190.55,0,103.053,4.97961
2.68805,1190.56,0.000801816,116.702,4.97958
2.73805,1190.56,0.0012713,125.42,4.97984
2.82805,1190.56,0.00155147,131.706,4.98117
2.91805,1190.56,0.00183403,137.862,4.98241
2.96805,1190.56,0.0023849,146.729,4.98316
3.01805,1190.56,0.00318575,160.02,4.98378
3.06805,1190.56,0.00401685,175.022,4.98402
3.11805,1190.56,0.00485029,190.356,4.98396
3.16805,1190.56,0.00567498,205.845,4.98362
3.21805,1190.56,0.00651688,221.628,4.98328
3.26805,1190.56,0.00735211,237.495,4.98317
3.31805,1190.56,0.00818822,253.313,4.98291
3.36805,1190.56,0.00901409,269.092,4.98252
3.41805,1190.56,0.00985034,284.785,4.98256
3.46805,1190.57,0.0106818,300.401,4.98285
3.51805,1190.57,0.011516,316.024,4.98279
3.56805,1190.57,0.01235,331.786,4.98228
3.61805,1190.57,0.0131861,347.612,4.98182
3.66805,1190.57,0.0140247,363.541,4.9816
3.71805,1190.57,0.0148558,379.728,4.98137
3.76805,1190.57,0.0156864,395.941,4.98094
3.81805,1190.57,0.0165075,412.237,4.98023
3.86805,1190.57,0.0173517,428.758,4.97908
3.91805,1190.57,0.0181833,445.352,4.97811
3.96805,1190.57,0.0190132,462.109,4.97826
4.01805,1190.57,0.0198472,479.073,4.97932
4.06805,1190.58,0.0206837,496.083,4.98036
4.11805,1190.58,0.0215167,512.955,4.98106
4.16805,1190.58,0.0223411,529.715,4.98144
4.21805,1190.58,0.0231805,546.612,4.98116
4.26805,1190.58,0.0240185,563.468,4.98035
4.31805,1190.58,0.0248484,580.176,4.97962
4.36805,1190.58,0.0256811,597.052,4.97878
4.41805,1190.58,0.0265145,614.133,4.97765
4.46805,1190.58,0.0273491,631.187,4.97681
4.51805,1190.58,0.0281863,648.141,4.97632
4.56805,1190.58,0.0290158,665.047,4.97589
4.61805,1190.58,0.0298462,682.005,4.97558
4.66805,1190.59,0.0306835,699.116,4.97543
4.71805,1190.59,0.0315189,716.342,4.97525
4.76805,1190.59,0.0323435,733.54,4.9751
4.81805,1190.59,0.0331793,750.659,4.97574
4.86805,1190.59,0.0340174,767.723,4.97709
4.91805,1190.59,0.0348534,784.574,4.97791
4.96805,1190.59,0.03568,801.266,4.97783
5.01805,1190.59,0.0365125,817.894,4.97692
5.06805,1190.59,0.0373478,834.392,4.97568
5.11805,1190.59,0.0381829,850.843,4.97492
5.16805,1190.59,0.0390109,867.309,4.97487
5.21805,1190.59,0.0398473,883.858,4.97487
5.26805,1190.6,0.0406783,900.356,4.97438
5.31805,1190.6,0.0415145,916.718,4.97401
5.36805,1190.6,0.0423542,933.16,4.9739
5.41805,1190.6,0.0431778,949.754,4.97392
5.46805,1190.6,0.0440144,966.415,4.97424
5.51805,1190.6,0.044848,983.113,4.97475
5.56805,1190.6,0.0456826,999.857,4.975
5.61805,1190.6,0.0465191,1016.44,4.97461
5.66805,1190.6,0.047344,1032.8,4.97399
5.71805,1190.6,0.0481877,1049.15,4.97355
5.76805,1190.6,0.0490147,1065.52,4.97363
5.81805,1190.6,0.0498444,1081.78,4.97432
5.86805,1190.61,0.0506833,1098.09,4.97502
5.91805,1190.61,0.0515152,1114.52,4.97549
5.96805,1190.61,0.052349,1130.84,4.97576
6.01805,1190.61,0.0531824,1147.05,4.97577
6.06805,1190.61,0.054009,1163.26,4.97564
6.11805,1190.61,0.0548474,1179.63,4.97558
6.16805,1190.61,0.0556912,1196.13,4.97548
6.21805,1190.61,0.0565094,1212.63,4.97523
6.26805,1190.61,0.0573507,1229.34,4.97475
6.31805,1190.61,0.0581828,1246.12,4.97412
6.36805,1190.61,0.0590154,1262.62,4.97356
6.41805,1190.61,0.0598444,1278.96,4.97335
6.46805,1190.62,0.0606843,1295.34,4.97335
6.51805,1190.62,0.0615148,1311.66,4.97328
6.56805,1190.62,0.0623505,1327.85,4.9731
6.61805,1190.62,0.0631797,1344.1,4.97291
6.66805,1190.62,0.0640143,1360.44,4.97318
6.71805,1190.62,0.0648482,1376.8,4.97372
6.76805,1190.62,0.0656804,1393.13,4.97425
6.81805,1190.62,0.0665152,1409.46,4.97486
6.86805,1190.62,0.0673472,1425.85,4.9754
6.91805,1190.62,0.0681802,1442.33,4.97614
6.96805,1190.62,0.069023,1458.73,4.97745
7.01805,1190.62,0.069843,1475.08,4.97883
7.06805,1190.63,0.0706769,1491.65,4.97951
7.11805,1190.63,0.0715147,1508.26,4.97936
7.16805,1190.63,0.0723512,1524.62,4.97871
7.21805,1190.63,0.0731756,1540.84,4.97794
7.26805,1190.63,0.0740157,1556.99,4.97721
7.31805,1190.63,0.0748517,1573.08,4.97673
7.36805,1190.63,0.0756885,1589.17,4.97673
7.41805,1190.63,0.0765156,1605.2,4.97694
7.46805,1190.63,0.0773401,1621.34,4.97708
7.51805,1190.63,0.0781883,1637.56,4.97717
7.56805,1190.63,0.0790208,1653.77,4.97713
7.61805,1190.63,0.0798535,1670,4.97686
7.66805,1190.64,0.0806851,1686.29,4.9764
7.71805,1190.64,0.0815175,1702.76,4.97612
7.76805,1190.64,0.0823495,1719.13,4.97618
7.81805,1190.64,0.083183,1735.5,4.97627
7.86805,1190.64,0.0840158,1751.9,4.97602
7.91805,1190.64,0.0848473,1768.16,4.97512
7.96805,1190.64,0.0856863,1784.12,4.97364
8.01805,1190.64,0.0865136,1799.85,4.97208
8.06805,1190.64,0.0873497,1815.58,4.97118
8.11805,1190.64,0.0881812,1831.43,4.97111
8.16805,1190.64,0.0890138,1847.52,4.97148
8.21805,1190.64,0.0898457,1863.6,4.97214
8.26805,1190.65,0.0906874,1879.57,4.97296
8.31805,1190.65,0.0915127,1895.68,4.97351
8.36805,1190.65,0.0923476,1911.79,4.97365
8.41805,1190.65,0.0931818,1927.8,4.97352
8.46805,1190.65,0.094012,1943.97,4.97323
8.51805,1190.65,0.0948517,1960.22,4.97284
8.56805,1190.65,0.0956849,1976.45,4.97252
8.61805,1190.65,0.0965138,1992.73,4.97236
8.66805,1190.65,0.097352,2008.95,4.9723
8.71805,1190.65,0.0981847,2025.02,4.97236
8.76805,1190.65,0.0990204,2040.96,4.97244
8.81805,1190.65,0.0998476,2056.82,4.97246
8.86805,1190.66,0.100683,2072.74,4.97245
8.91805,1190.66,0.101523,2088.75,4.97259
8.96805,1190.66,0.102354,2104.68,4.97293
9.01805,1190.66,0.103179,2120.43,4.97334
9.06805,1190.66,0.104011,2136.18,4.97394
9.11805,1190.66,0.104845,2152.08,4.97479
9.16805,1190.66,0.105686,2167.9,4.97577
9.21805,1190.66,0.106514,2183.78,4.97686
9.26805,1190.66,0.107348,2199.76,4.97779
9.31805,1190.66,0.10818,2215.78,4.97828
9.36805,1190.66,0.10902,2231.86,4.97843
9.41805,1190.66,0.109848,2247.68,4.97834
9.46805,1190.67,0.110681,2263.38,4.97801
9.51805,1190.67,0.111512,2279.1,4.97751
9.56805,1190.67,0.112353,2294.7,4.97686
9.61805,1190.67,0.11318,2310.23,4.97619
9.66805,1190.67,0.114012,2325.82,4.97582
9.71805,1190.67,0.114847,2341.52,4.97597
9.76805,1190.67,0.115693,2357.28,4.97633
9.81805,1190.67,0.116512,2372.99,4.97657
9.86805,1190.67,0.117352,2388.56,4.9768
9.91805,1190.67,0.118184,2404.23,4.97683
9.96805,1190.67,0.119017,2420.04,4.97657
10.0181,1190.67,0.119852,2435.67,4.97618
10.0681,1190.68,0.120688,2451.22,4.9758
10.118,1190.68,0.121508,2467.05,4.97576
10.168,1190.68,0.122354,2483.09,4.97588
10.2181,1190.68,0.123191,2498.86,4.97591
10.2681,1190.68,0.124019,2514.33,4.97593
10.3181,1190.68,0.124855,2529.88,4.9759
10.368,1190.68,0.125679,2545.4,4.97584
10.418,1190.68,0.126517,2560.89,4.97587
10.4681,1190.68,0.127349,2576.44,4.97594
10.5181,1190.68,0.128182,2592.15,4.97591
10.5681,1190.68,0.129015,2607.83,4.97588
10.618,1190.68,0.129852,2623.37,4.97595
10.668,1190.69,0.130682,2638.94,4.97611
10.7181,1190.69,0.131515,2654.53,4.97633
10.7681,1190.69,0.132351,2670.26,4.97655
10.8181,1190.69,0.133182,2686.09,4.97681
10.868,1190.69,0.134006,2701.78,4.97692
10.918,1190.69,0.134847,2717.46,4.97679
10.9681,1190.69,0.135684,2733.1,4.97664
11.0181,1190.69,0.136526,2748.43,4.97653
11.0681,1190.69,0.137348,2763.52,4.97648
11.118,1190.69,0.138176,2778.64,4.97644
11.168,1190.69,0.139016,2793.85,4.97639
11.2181,1190.69,0.13985,2809.11,4.97642
11.2681,1190.7,0.14068,2824.52,4.97662
11.3181,1190.7,0.14152,2839.94,4.97694
11.368,1190.7,0.142352,2855.36,4.97713
11.418,1190.7,0.143181,2870.76,4.97713
11.4681,1190.7,0.144012,2886.14,4.97712
11.5181,1190.7,0.144845,2901.64,4.97723
11.5681,1190.7,0.145675,2917.2,4.97741
11.618,1190.7,0.146517,2932.76,4.97764
11.668,1190.7,0.147347,2948.37,4.97788
11.7181,1190.7,0.148181,2963.94,4.97814
11.7681,1190.7,0.149016,2979.3,4.97845
11.8181,1190.7,0.149849,2994.48,4.97862
11.868,1190.71,0.150684,3009.58,4.97857
11.918,1190.71,0.151514,3024.71,4.97842
11.9681,1190.71,0.152349,3039.91,4.97825
12.0181,1190.71,0.153184,3055.14,4.97807
12.0681,1190.71,0.154014,3070.4,4.97776
12.118,1190.71,0.154844,3085.6,4.97721
12.168,1190.71,0.155687,3100.8,4.97678
12.2181,1190.71,0.156517,3116.15,4.9767
12.2681,1190.71,0.157351,3131.49,4.97668
12.3181,1190.71,0.158178,3146.87,4.97662
12.368,1190.71,0.159011,3162.38,4.97655
12.418,1190.71,0.159854,3177.85,4.97644
12.4681,1190.72,0.160683,3193.18,4.97634
12.5181,1190.72,0.161513,3208.38,4.97621
12.5681,1190.72,0.162355,3223.55,4.97596
12.618,1190.72,0.163184,3238.75,4.9757
12.668,1190.72,0.164018,3253.79,4.97544
12.7181,1190.72,0.164848,3268.79,4.9752
12.7681,1190.72,0.165681,3284,4.97495
12.8181,1190.72,0.166518,3299.27,4.97456
12.868,1190.72,0.167356,3314.46,4.97403
12.918,1190.72,0.168174,3329.62,4.97344
12.9681,1190.72,0.169016,3344.87,4.97296
13.0181,1190.72,0.169845,3360.23,4.97261
13.0681,1190.73,0.170684,3375.6,4.97231
13.118,1190.73,0.171516,3390.91,4.97202
13.168,1190.73,0.172346,3406.13,4.9717
13.2181,1190.73,0.173183,3421.36,4.97148
13.2681,1190.73,0.174014,3436.49,4.97134
13.3181,1190.73,0.174846,3451.56,4.97117
13.368,1190.73,0.175679,3466.56,4.97108
13.418,1190.73,0.176518,3481.54,4.97117
13.4681,1190.73,0.177346,3496.62,4.9714
13.5181,1190.73,0.178181,3511.62,4.97174
13.5681,1190.73,0.179014,3526.62,4.97203
13.618,1190.73,0.179849,3541.66,4.97218
13.668,1190.74,0.180677,3556.52,4.97229
13.7181,1190.74,0.181516,3571.22,4.9724
13.7681,1190.74,0.182345,3586.19,4.97255
13.8181,1190.74,0.183186,3601.29,4.97269
13.868,1190.74,0.184021,3616.32,4.97276
13.918,1190.74,0.184852,3631.43,4.97282
13.9681,1190.74,0.185683,3646.4,4.97282
14.0181,1190.74,0.186518,3661.24,4.97273
14.0681,1190.74,0.187344,3675.99,4.97261
14.118,1190.74,0.188177,3690.72,4.97249
14.168,1190.74,0.189019,3705.44,4.97236
14.2181,1190.74,0.189849,3720.01,4.97223
14.2681,1190.75,0.190688,3734.58,4.97217
14.3181,1190.75,0.191516,3749.33,4.97213
14.368,1190.75,0.192348,3764.22,4.97209
14.418,1190.75,0.193183,3779,4.97208
14.4681,1190.75,0.194016,3793.58,4.9721
14.5181,1190.75,0.194844,3808.33,4.9721
14.5681,1190.75,0.195682,3823.27,4.97207
14.618,1190.75,0.196521,3838.11,4.97203
14.668,1190.75,0.197353,3852.83,4.97194
14.7181,1190.75,0.198176,3867.59,4.97185
14.7681,1190.75,0.199019,3882.33,4.97181
14.8181,1190.75,0.199858,3896.99,4.97171
14.868,1190.76,0.200686,3911.6,4.97157
14.918,1190.76,0.201517,3926.05,4.9714
14.9681,1190.76,0.202346,3940.57,4.97122
15.0181,1190.76,0.203182,3955.25,4.9711
15.0681,1190.76,0.204019,3969.87,4.97102
15.118,1190.76,0.204844,3984.46,4.97096
15.168,1190.76,0.205685,3999.06,4.97094
15.2181,1190.76,0.206518,4013.67,4.97101
15.2681,1190.76,0.20735,4028.3,4.97127
15.3181,1190.76,0.208189,4042.72,4.97157
15.368,1190.76,0.209009,4057.26,4.97181
15.418,1190.76,0.209853,4072.06,4.97202
15.4681,1190.77,0.210683,4086.88,4.9722
15.5181,1190.77,0.211515,4101.51,4.97234
15.5681,1190.77,0.212349,4115.96,4.97244
15.618,1190.77,0.213176,4130.34,4.97261
15.668,1190.77,0.21402,4144.63,4.97278
15.7181,1190.77,0.214845,4158.86,4.97285
15.7681,1190.77,0.215679,4173.14,4.97294
15.8181,1190.77,0.216516,4187.52,4.97303
15.868,1190.77,0.217348,4201.91,4.97307
15.918,1190.77,0.21818,4216.28,4.97308
15.9681,1190.77,0.219015,4230.52,4.97312
16.0181,1190.77,0.219847,4244.83,4.97315
16.0681,1190.78,0.220682,4259.33,4.97311
16.118,1190.78,0.221515,4273.78,4.97303
16.168,1190.78,0.222348,4288.23,4.97293
16.2181,1190.78,0.223177,4302.79,4.9728
16.2681,1190.78,0.224016,4317.15,4.97264
16.3181,1190.78,0.224853,4331.27,4.97247
16.368,1190.78,0.225687,4345.36,4.97231
16.418,1190.78,0.226517,4359.31,4.97213
16.4681,1190.78,0.227348,4373.13,4.97198
16.5181,1190.78,0.228182,4387.04,4.97187
16.5681,1190.78,0.229014,4401.09,4.97176
16.618,1190.78,0.229846,4415.25,4.97169
16.668,1190.79,0.230678,4429.5,4.97171
16.7181,1190.79,0.231516,4443.54,4.97176
16.7681,1190.79,0.232353,4457.49,4.97188
16.8181,1190.79,0.233178,4471.63,4.97213
16.868,1190.79,0.234016,4485.83,4.97244
16.918,1190.79,0.234848,4500.02,4.97266
16.9681,1190.79,0.235682,4514.23,4.97283
17.0181,1190.79,0.236515,4528.44,4.973
17.0681,1190.79,0.237348,4542.45,4.97312
17.118,1190.79,0.238181,4556.16,4.9732
17.168,1190.79,0.239018,4569.62,4.97322
17.2181,1190.79,0.239843,4583.16,4.97313
17.2681,1190.8,0.240683,4596.95,4.97304
17.3181,1190.8,0.241516,4610.74,4.97294
17.368,1190.8,0.242345,4624.49,4.97278
17.418,1190.8,0.243188,4638.26,4.97264
17.4681,1190.8,0.244016,4651.96,4.97248
17.5181,1190.8,0.244844,4665.64,4.97235
17.5681,1190.8,0.245683,4679.24,4.97232
17.618,1190.8,0.246514,4692.89,4.97235
17.668,1190.8,0.247349,4706.67,4.97245
17.7181,1190.8,0.248183,4720.41,4.97271
17.7681,1190.8,0.249014,4734.14,4.97293
17.8181,1190.8,0.249846,4747.69,4.97308
17.868,1190.81,0.25069,4761.03,4.97326
17.918,1190.81,0.251517,4774.27,4.97345
17.9681,1190.81,0.252352,4787.54,4.9737
18.0181,1190.81,0.253182,4800.92,4.97398
18.0681,1190.81,0.254015,4814.32,4.97427
18.118,1190.81,0.254854,4827.65,4.97456
18.168,1190.81,0.255684,4840.93,4.97477
18.2181,1190.81,0.256515,4854.23,4.97495
18.2681,1190.81,0.257356,4866.56,4.97514
18.3181,1190.81,0.258186,4878.77,4.97532
18.368,1190.81,0.259019,4892.06,4.9755
18.418,1190.81,0.259851,4905.79,4.9757
18.4681,1190.82,0.260687,4919.58,4.9759
18.5181,1190.82,0.261514,4933.03,4.97609
18.5681,1190.82,0.262351,4946.19,4.9763
18.618,1190.82,0.263179,4959.22,4.97657
18.668,1190.82,0.264015,4972.19,4.97693
18.7181,1190.82,0.264855,4985.1,4.97731
18.7681,1190.82,0.265683,4997.88,4.97769
18.8181,1190.82,0.266513,5010.5,4.97802
18.868,1190.82,0.26735,5023.3,4.97827
18.918,1190.82,0.268186,5036.14,4.97848
18.9681,1190.82,0.269015,5048.88,4.97867
19.0181,1190.82,0.269843,5061.69,4.9789
19.0681,1190.83,0.270691,5074.48,4.97916
19.118,1190.83,0.27152,5087.38,4.97943
19.168,1190.83,0.272352,5100.05,4.97969
19.2181,1190.83,0.273178,5112.5,4.97989
19.2681,1190.83,0.274019,5125.25,4.98006
19.3181,1190.83,0.274853,5138.03,4.98019
19.368,1190.83,0.275685,5150.62,4.98026
19.418,1190.83,0.276517,5163.01,4.98033
19.4681,1190.83,0.277348,5175.36,4.98041
19.5181,1190.83,0.278184,5187.78,4.98043
19.5681,1190.83,0.279013,5200.1,4.98042
19.618,1190.83,0.279847,5212.45,4.98041
19.668,1190.84,0.280683,5224.9,4.98036
19.7181,1190.84,0.28151,5237.21,4.98031
19.7681,1190.84,0.282345,5249.39,4.98024
19.8181,1190.84,0.283174,5261.74,4.98017
19.868,1190.84,0.284018,5274.17,4.9801
19.918,1190.84,0.284854,5286.55,4.97996
19.9681,1190.84,0.285685,5298.93,4.97978
20.0181,1190.84,0.286509,5311.23,4.97961
20.0681,1190.84,0.287348,5323.4,4.97944
20.118,1190.84,0.288185,5334.94,4.97923
20.168,1190.84,0.289018,5342.14,4.97899
20.2181,1190.84,0.289845,5350.24,4.97875
20.2681,1190.85,0.290684,5363.29,4.97849
20.3181,1190.85,0.29152,5376.44,4.97824
20.368,1190.85,0.292362,5389.27,4.97797
20.418,1190.85,0.293181,5401.85,4.97767
20.4681,1190.85,0.294012,5414.22,4.97739
20.5181,1190.85,0.294857,5426.36,4.97714
20.5681,1190.85,0.295686,5438.48,4.97692
20.618,1190.85,0.296514,5450.62,4.97669
20.668,1190.85,0.297349,5462.83,4.97646
20.7181,1190.85,0.298184,5475.08,4.97625
20.7681,1190.85,0.299019,5487.14,4.97608
20.8181,1190.85,0.29985,5499.06,4.97588
20.868,1190.86,0.30068,5510.93,4.97571
20.918,1190.86,0.301516,5522.57,4.97557
20.9681,1190.86,0.302343,5534.04,4.97546
21.0181,1190.86,0.303174,5545.52,4.97533
21.0681,1190.86,0.304009,5557.18,4.97519
21.118,1190.86,0.30485,5568.85,4.97508
21.168,1190.86,0.305686,5580.34,4.97498
21.2181,1190.86,0.306517,5591.8,4.9749
21.2681,1190.86,0.307347,5603.14,4.97482
21.3181,1190.86,0.30818,5614.54,4.97476
21.368,1190.86,0.309019,5625.99,4.97478
21.418,1190.86,0.309846,5637.44,4.97486
21.4681,1190.87,0.310682,5648.83,4.97495
21.5181,1190.87,0.311518,5660.1,4.97507
21.5681,1190.87,0.31235,5671.38,4.97516
21.618,1190.87,0.313177,5682.55,4.97525
21.668,1190.87,0.314018,5693.6,4.97538
21.7181,1190.87,0.314848,5704.62,4.9755
21.7681,1190.87,0.315683,5715.5,4.97564
21.8181,1190.87,0.316513,5726.3,4.97578
21.868,1190.87,0.317351,5737.34,4.97589
21.918,1190.87,0.318182,5748.38,4.97596
21.9681,1190.87,0.319015,5759.2,4.97602
22.0181,1190.87,0.319853,5769.83,4.97609
22.0681,1190.88,0.320675,5780.55,4.97615
22.118,1190.88,0.321515,5791.4,4.97619
22.168,1190.88,0.322347,5802.13,4.97623
22.2181,1190.88,0.323172,5812.82,4.97628
22.2681,1190.88,0.323999,5823.63,4.97634
22.3181,1190.88,0.324848,5834.44,4.97637
22.368,1190.88,0.325688,5842.42,4.9764
22.418,1190.88,0.326504,5849.56,4.9764
22.4681,1190.88,0.327343,5859.74,4.97637
22.5181,1190.88,0.328183,5870.7,4.97637
22.5681,1190.88,0.329016,5881.49,4.9764
22.618,1190.88,0.329846,5892.3,4.97641
22.668,1190.89,0.330681,5902.88,4.97636
22.7181,1190.89,0.331515,5913.38,4.97631
22.7681,1190.89,0.332353,5923.78,4.97631
22.8181,1190.89,0.333183,5934.01,4.97632
22.868,1190.89,0.334013,5944.21,4.97629
22.918,1190.89,0.334853,5954.44,4.97625
22.9681,1190.89,0.335688,5964.62,4.97624
23.0181,1190.89,0.33652,5974.58,4.97624
23.0681,1190.89,0.337349,5984.55,4.97622
23.118,1190.89,0.338181,5994.52,4.97619
23.168,1190.89,0.339019,6004.38,4.97617
23.2181,1190.89,0.339853,6014.01,4.97613
23.2681,1190.9,0.340681,6023.38,4.97607
23.3181,1190.9,0.341523,6032.84,4.97602
23.368,1190.9,0.342346,6042.26,4.97598
23.418,1190.9,0.343181,6051.57,4.97593
23.4681,1190.9,0.344011,6060.91,4.97589
23.5181,1190.9,0.344846,6070.15,4.97587
23.5681,1190.9,0.34569,6079.36,4.97586
23.618,1190.9,0.346521,6088.52,4.97589
23.668,1190.9,0.347349,6097.72,4.97593
23.7181,1190.9,0.348186,6106.94,4.97595
23.7681,1190.9,0.349021,6115.28,4.97595
23.8181,1190.9,0.349845,6123.6,4.97593
23.868,1190.91,0.350678,6132.73,4.97591
23.918,1190.91,0.351517,6141.95,4.97588
23.9681,1190.91,0.352355,6150.88,4.97584
24.0181,1190.91,0.353183,6159.37,4.97579
24.0681,1190.91,0.354015,6167.66,4.97575
24.118,1190.91,0.354847,6175.89,4.97568
24.168,1190.91,0.355684,6184.18,4.97559
24.2181,1190.91,0.356514,6192.48,4.97551
24.2681,1190.91,0.357349,6200.69,4.97542
24.3181,1190.91,0.358177,6208.77,4.97535
24.368,1190.91,0.35902,6216.85,4.97529
24.418,1190.91,0.359854,6224.88,4.97524
24.4681,1190.92,0.360685,6232.86,4.97517
24.5181,1190.92,0.361515,6240.73,4.9751
24.5681,1190.92,0.362348,6248.44,4.97501
24.618,1190.92,0.36318,6256.13,4.97493
24.668,1190.92,0.364016,6263.66,4.97487
24.7181,1190.92,0.364843,6271.04,4.97478
24.7681,1190.92,0.36568,6278.25,4.97467
24.8181,1190.92,0.366521,6285.3,4.97457
24.868,1190.92,0.367348,6292.25,4.97445
24.918,1190.92,0.368184,6299.18,4.97434
24.9681,1190.92,0.36902,6306.19,4.97421
25.0181,1190.92,0.369841,6313.1,4.97405
25.0681,1190.93,0.370679,6319.88,4.9739
25.118,1190.93,0.371512,6326.66,4.97378
25.168,1190.93,0.372357,6333.45,4.97366
25.2181,1190.93,0.373186,6340.21,4.97357
25.2681,1190.93,0.374019,6346.81,4.97347
25.3181,1190.93,0.374843,6353.27,4.97339
25.368,1190.93,0.375685,6359.66,4.97329
25.418,1190.93,0.37652,6365.88,4.97311
25.4681,1190.93,0.377349,6371.9,4.97297
25.548,1190.93,0.378682,6375.38,4.97278
25.6481,1190.94,0.380354,6377.99,4.97275
25.6981,1190.94,0.381178,6386.26,4.97275
25.748,1190.94,0.382011,6394.05,4.97276
25.798,1190.94,0.382852,6401.36,4.97284
25.8481,1190.94,0.38368,6408.19,4.97295
25.8981,1190.94,0.384511,6414.74,4.973
25.9481,1190.94,0.385349,6421.17,4.97304
25.998,1190.94,0.386183,6427.35,4.97311
26.048,1190.94,0.387022,6433.34,4.9732
26.0981,1190.94,0.387846,6439.2,4.97335
26.1481,1190.94,0.388676,6444.77,4.97351
26.1981,1190.94,0.389518,6450.08,4.97364
26.2681,1190.95,0.390686,6457.14,4.97387
26.358,1190.95,0.392181,6466.02,4.97412
26.4581,1190.95,0.393846,6475.94,4.97427
26.558,1190.95,0.395515,6485.52,4.97449
26.6581,1190.95,0.397182,6494.71,4.97468
26.7581,1190.95,0.398845,6504.14,4.97485
26.858,1190.96,0.400519,6513.48,4.97498
26.9581,1190.96,0.402173,6522.12,4.97505
27.058,1190.96,0.403849,6530.21,4.97519
27.1581,1190.96,0.405514,6538.27,4.97543
27.2581,1190.96,0.407187,6546.68,4.97565
27.358,1190.96,0.408847,6554.7,4.97585
27.4581,1190.97,0.410517,6562.77,4.97613
27.558,1190.97,0.412182,6570.81,4.97637
27.6581,1190.97,0.413856,6578.86,4.97661
27.7581,1190.97,0.415517,6586.12,4.9767
27.858,1190.97,0.417183,6592.98,4.97682
27.9581,1190.97,0.418852,6599.95,4.97693
28.058,1190.98,0.420525,6607.45,4.97709
28.1581,1190.98,0.422175,6614.17,4.97727
28.2581,1190.98,0.423849,6621.29,4.97727
28.358,1190.98,0.425511,6628.33,4.97736
28.4581,1190.98,0.427182,6635.25,4.97747
28.558,1190.98,0.428846,6641.47,4.97747
28.6581,1190.99,0.430518,6647.48,4.97765
28.7581,1190.99,0.43218,6653.85,4.97777
28.858,1190.99,0.433853,6660.48,4.97773
28.9581,1190.99,0.435515,6666.78,4.97793
29.058,1190.99,0.437184,6673.24,4.97804
29.1581,1190.99,0.438846,6679.61,4.97821
29.2581,1191,0.440521,6685.8,4.97839
29.358,1191,0.442179,6691.41,4.97857
29.4581,1191,0.443851,6697.38,4.97896
29.558,1191,0.445514,6703.45,4.97922
29.6581,1191,0.447183,6709.19,4.97962
29.8481,1191.01,0.450345,6714.49,5.06329
29.9481,1191.01,0.452013,6720.89,5.06321
30.048,1191.01,0.453689,6727.16,5.0631
30.1481,1191.01,0.455348,6732.93,5.06294
30.248,1191.01,0.457016,6738.63,5.06281
30.3481,1191.01,0.458687,6744.43,5.06273
30.4481,1191.02,0.46035,6750.02,5.06258
30.548,1191.02,0.462016,6755.72,5.06246
30.6481,1191.02,0.463682,6761.32,5.06227
30.748,1191.02,0.465348,6766.55,5.06202
30.8981,1191.02,0.467855,6773.89,5.06161
31.0181,1191.02,0.469853,6780.08,5.0613
31.118,1191.03,0.471511,6785.55,5.06109
31.2181,1191.03,0.47318,6790.86,5.06106
31.3181,1191.03,0.474854,6796.34,5.06099
31.418,1191.03,0.476516,6801.61,5.06095
31.5281,1191.03,0.478348,6807.28,5.06112
31.678,1191.04,0.480851,6814.22,5.06173
31.808,1191.04,0.483007,6820.54,5.06233
31.938,1191.04,0.485179,6826.9,5.06278
32.048,1191.04,0.487015,6832.56,5.06306
32.1481,1191.04,0.488685,6837.74,5.06351
32.2681,1191.05,0.490681,6843.74,5.06373
32.418,1191.05,0.49318,6850.39,5.06422
32.558,1191.05,0.495515,6857.11,5.06451
32.6981,1191.05,0.497851,6863.85,5.06518
32.878,1191.06,0.50085,6869.6,5.06872
33.0281,1191.06,0.503347,6874.55,5.09965
33.1381,1191.06,0.505178,6880.55,5.10039
33.2581,1191.06,0.50719,6886.71,5.10088
33.3881,1191.06,0.509353,6893.23,5.10118
33.538,1191.07,0.511852,6900.47,5.10132
33.6581,1191.07,0.513848,6906.49,5.10168
33.798,1191.07,0.516177,6912.82,5.10198
33.9481,1191.07,0.518683,6918.89,5.10228
34.0981,1191.08,0.521183,6925.27,5.10262
34.248,1191.08,0.523676,6931.46,5.10309
34.3981,1191.08,0.526178,6937.55,5.1035
34.548,1191.08,0.528689,6944.26,5.10407
34.6981,1191.09,0.531183,6949.86,5.10478
34.8481,1191.09,0.533678,6955.84,5.10549
34.998,1191.09,0.536181,6962.24,5.10761
35.178,1191.09,0.539183,6968.44,5.15109
35.3281,1191.1,0.541677,6974.86,5.15139
35.478,1191.1,0.544182,6980.28,5.15159
35.628,1191.1,0.54668,6986.12,5.15181
35.7781,1191.1,0.549184,6992.26,5.15202
35.928,1191.11,0.551682,6998.68,5.15237
36.0781,1191.11,0.554178,7004.69,5.15262
36.248,1191.11,0.557013,7010.53,5.15304
36.3981,1191.11,0.559512,7016.39,5.15332
36.548,1191.12,0.562017,7022.51,5.15381
36.6981,1191.12,0.564513,7028.79,5.15447
36.8481,1191.12,0.567012,7034.5,5.15525
37.038,1191.13,0.57018,7039.76,5.17494
37.1981,1191.13,0.572843,7045.41,5.17562
37.3481,1191.13,0.57535,7051,5.17587
37.498,1191.13,0.577843,7056.89,5.17606
37.668,1191.14,0.580678,7062.54,5.17642
37.858,1191.14,0.583848,7068.66,5.1766
38.0181,1191.14,0.586513,7074.29,5.17678
38.178,1191.14,0.589183,7080.16,5.17701
38.3281,1191.15,0.59168,7085.41,5.17727
38.5281,1191.15,0.595014,7091.34,5.17775
38.7181,1191.15,0.598184,7097.23,5.18716
38.9081,1191.16,0.601349,7102.97,5.1956
39.058,1191.16,0.603845,7108.52,5.19598
39.2581,1191.16,0.607184,7114.16,5.19654
39.4481,1191.17,0.610354,7120.13,5.19696
39.628,1191.17,0.61335,7121.83,5.19731
39.7781,1191.17,0.615852,7125.14,5.19766
39.8981,1191.17,0.617848,7131.08,5.19781
40.048,1191.18,0.620348,7136.81,5.19801
40.1981,1191.18,0.622846,7142.46,5.19861
40.368,1191.18,0.625682,7148.14,5.20599
40.538,1191.18,0.628519,7153.32,5.22108
40.728,1191.19,0.631681,7158.92,5.22178
40.9481,1191.19,0.635353,7164.84,5.22219
41.1481,1191.19,0.638677,7170.99,5.22287
41.3381,1191.2,0.64185,7177.03,5.22382
41.5681,1191.2,0.645675,7182.83,5.22544
41.788,1191.2,0.649349,7188.3,5.23904
41.988,1191.21,0.652678,7193.98,5.24084
42.1981,1191.21,0.656188,7199.63,5.24149
42.418,1191.21,0.659849,7205.14,5.24257
42.628,1191.22,0.663348,7210.81,5.24365
42.8281,1191.22,0.666683,7216.53,5.24891
43.0781,1191.23,0.670852,7222.08,5.25298
43.288,1191.23,0.674344,7227.28,5.25418
43.498,1191.23,0.677854,7232.87,5.25576
43.728,1191.24,0.681674,7238.37,5.25857
43.988,1191.24,0.686016,7243.85,5.2613
44.2181,1191.24,0.689848,7249.61,5.26415
44.4581,1191.25,0.693851,7255.35,5.26755
44.748,1191.25,0.698681,7261,5.27326
44.998,1191.26,0.70285,7266.75,5.27656
45.238,1191.26,0.706853,7272.29,5.28018
45.5181,1191.27,0.711519,7277.73,5.2857
45.7681,1191.27,0.715681,7283.03,5.29073
46.0181,1191.27,0.719847,7288.42,5.29581
46.298,1191.28,0.724524,7293.5,5.30171
46.5881,1191.28,0.729348,7299.03,5.30832
46.8881,1191.29,0.734342,7304.21,5.31445
47.178,1191.29,0.739182,7309.64,5.32008
47.438,1191.3,0.743517,7314.96,5.32439
47.748,1191.3,0.748687,7319.62,5.32896
48.048,1191.31,0.753683,7325.35,5.33269
48.358,1191.31,0.758849,7330.36,5.33744
48.688,1191.32,0.76435,7335.16,5.34152
48.998,1191.32,0.76952,7340.49,5.34536
49.308,1191.33,0.774686,7344.21,5.34927
49.628,1191.33,0.780016,7349.27,5.35283
49.9481,1191.34,0.785353,7353.31,5.35618
50.288,1191.35,0.791017,7358.11,5.36033
50.5981,1191.35,0.796184,7361.88,5.36377
50.918,1191.36,0.801522,7365.49,5.36767
51.248,1191.36,0.807016,7370.4,5.37161
51.5781,1191.37,0.812519,7372.97,5.37622
51.9081,1191.37,0.81802,7377.02,5.38368
52.2181,1191.38,0.823182,7379.21,5.39547
52.548,1191.38,0.828684,7382.26,5.40605
52.858,1191.39,0.833848,7386.04,5.41542
53.188,1191.39,0.839346,7388.29,5.42573
53.5081,1191.4,0.844683,7391.41,5.43506
53.8181,1191.4,0.849856,7392.87,5.44203
54.1381,1191.41,0.855181,7395.79,5.44842
54.4481,1191.42,0.860349,7397.85,5.45252
54.7581,1191.42,0.865509,7399.25,5.45525
55.0781,1191.43,0.870849,7401.33,5.45871
55.4081,1191.43,0.876353,7402.28,5.46217
55.738,1191.44,0.881843,7403.92,5.46572
56.048,1191.44,0.887022,7403.97,5.46907
56.378,1191.45,0.89252,7404.99,5.47346
56.688,1191.45,0.897687,7405.7,5.47781
57.0181,1191.46,0.903192,7405.79,5.48189
57.3481,1191.46,0.908685,7407.26,5.4865
57.668,1191.47,0.91402,7406.81,5.49174
57.998,1191.47,0.919514,7407.17,5.49813
58.3181,1191.48,0.924848,7405.66,5.50338
58.6381,1191.49,0.930186,7405.21,5.50847
58.9581,1191.49,0.935521,7404.92,5.51375
59.288,1191.5,0.941016,7403.61,5.51942
59.5981,1191.5,0.946179,7403.33,5.52437
59.9081,1191.51,0.951346,7400.94,5.52955
60.2181,1191.51,0.956517,7399.81,5.53451
60.538,1191.52,0.961847,7397.72,5.53872
60.8481,1191.52,0.96702,7395.92,5.54306
61.168,1191.53,0.972352,7394.79,5.5474
61.478,1191.53,0.97752,7391.52,5.5525
61.8181,1191.54,0.98318,7389.08,5.55862
62.1481,1191.54,0.988681,7385.43,5.56493
62.4681,1191.55,0.994019,7382.73,5.57047
62.788,1191.55,0.999345,7379.49,5.57678
63.118,1191.56,1.00485,7375.48,5.58483
63.438,1191.57,1.01018,7372.02,5.59297
63.738,1191.57,1.01519,7367.03,5.60043
64.058,1191.58,1.02051,7362.85,5.60814
64.3381,1191.58,1.02518,7358.06,5.61471
64.618,1191.58,1.02986,7352.89,5.62091
64.928,1191.59,1.03502,7347.92,5.62652
65.178,1191.59,1.03918,7342.25,5.63052
65.478,1191.6,1.04418,7336.89,5.63611
65.7781,1191.6,1.04919,7331.45,5.64062
65.998,1191.61,1.05285,7326.09,5.6431
66.2681,1191.61,1.05735,7320.46,5.64625
66.538,1191.62,1.06186,7314.78,5.6497
66.748,1191.62,1.06535,7309.24,5.65298
66.988,1191.62,1.06935,7303.56,5.65649
67.228,1191.63,1.07335,7297.81,5.66019
67.3981,1191.63,1.07619,7292.19,5.66318
67.5681,1191.63,1.07901,7286.63,5.66589
67.7681,1191.64,1.08235,7280.69,5.67033
67.9681,1191.64,1.08568,7274.83,5.67588
68.118,1191.64,1.08818,7269.39,5.67923
68.2681,1191.65,1.09068,7264.15,5.6815
68.438,1191.65,1.09351,7258.36,5.68459
68.618,1191.65,1.09652,7252.69,5.68915
68.7681,1191.65,1.09902,7247.34,5.69313
68.918,1191.66,1.10152,7241.26,5.69621
69.0681,1191.66,1.10401,7235.6,5.70002
69.2181,1191.66,1.10652,7230.2,5.7042
69.378,1191.66,1.10919,7224.5,5.70782
69.5281,1191.67,1.11169,7218.72,5.71126
69.6481,1191.67,1.11368,7212.25,5.71371
69.748,1191.67,1.11534,7206.63,5.71584
69.8481,1191.67,1.11702,7201.25,5.71762
69.9481,1191.67,1.11868,7195.36,5.71941
70.048,1191.68,1.12035,7189.22,5.72114
70.1481,1191.68,1.12201,7183.06,5.72261
70.248,1191.68,1.12368,7177.05,5.72427
70.3481,1191.68,1.12535,7170.17,5.72591
70.4481,1191.68,1.12702,7163.42,5.7273
70.548,1191.68,1.12869,7156.89,5.7287
70.6481,1191.69,1.13035,7151.05,5.72976
70.748,1191.69,1.13201,7144.48,5.73055
70.8481,1191.69,1.13368,7137.37,5.73149
70.9481,1191.69,1.13533,7129.91,5.73255
71.048,1191.69,1.13702,7121.65,5.73377
71.1481,1191.69,1.13868,7111.98,5.73504
71.238,1191.7,1.14018,7103.14,5.7363
71.288,1191.7,1.14102,7097.87,5.73706
71.3381,1191.7,1.14185,7092.59,5.73771
71.438,1191.7,1.14351,7083.04,5.73897
71.5281,1191.7,1.14502,7074.09,5.73996
71.5981,1191.7,1.14619,7067.1,5.7408
71.6481,1191.7,1.14702,7061.64,5.74151
71.6981,1191.7,1.14785,7055.85,5.74222
71.748,1191.7,1.14868,7050.28,5.74289
71.798,1191.7,1.14952,7044.59,5.74349
71.8481,1191.71,1.15035,7038.43,5.74403
71.8981,1191.71,1.15119,7031.7,5.74453
71.9481,1191.71,1.15202,7024.59,5.74506
71.998,1191.71,1.15285,7017.12,5.74564
72.048,1191.71,1.15368,7009.29,5.7462
72.0981,1191.71,1.15452,7001.36,5.74673
72.1481,1191.71,1.15535,6993.2,5.74725
72.1981,1191.71,1.15618,6984.69,5.74778
72.248,1191.71,1.15702,6976.03,5.74832
72.298,1191.71,1.15785,6967.33,5.749
72.3481,1191.71,1.15868,6958.56,5.74974
72.3981,1191.71,1.15952,6949.59,5.75053
72.4481,1191.72,1.16035,6940.83,5.75126
72.498,1191.72,1.16118,6932.74,5.75188
72.548,1191.72,1.16201,6924.91,5.75248
72.5981,1191.72,1.16285,6917.17,5.75313
72.6481,1191.72,1.16369,6909.21,5.75392
72.6981,1191.72,1.16452,6900.93,5.75484
72.748,1191.72,1.16535,6892.82,5.75574
72.798,1191.72,1.16618,6885.15,5.75652
72.8481,1191.72,1.16702,6877.57,5.75723
72.8981,1191.72,1.16785,6869.48,5.75804
72.9481,1191.72,1.16868,6861.09,5.75887
72.998,1191.72,1.16951,6852.61,5.75965
73.048,1191.73,1.17035,6844.18,5.7605
73.0981,1191.73,1.17119,6835.91,5.76123
73.1481,1191.73,1.17202,6827.6,5.76198
73.1981,1191.73,1.17285,6819.44,5.76287
73.248,1191.73,1.17368,6811.74,5.7638
73.298,1191.73,1.17451,6804.52,5.76483
73.3481,1191.73,1.17535,6797.54,5.76586
73.3981,1191.73,1.17618,6790.59,5.76689
73.4481,1191.73,1.17701,6783.84,5.76776
73.498,1191.73,1.17786,6777.19,5.76852
73.548,1191.73,1.17868,6770.65,5.76939
73.5981,1191.73,1.17952,6764.4,5.77042
73.6481,1191.74,1.18035,6758.26,5.77137
73.6981,1191.74,1.18118,6752.03,5.77229
73.748,1191.74,1.18201,6745.74,5.77343
73.798,1191.74,1.18285,6739.64,5.77462
73.8481,1191.74,1.18369,6733.43,5.77577
73.8981,1191.74,1.18452,6727,5.77703
73.9481,1191.74,1.18535,6720.53,5.77839
73.998,1191.74,1.18618,6713.7,5.7798
74.048,1191.74,1.18702,6706.76,5.78124
74.0981,1191.74,1.18785,6699.8,5.78261
74.1481,1191.74,1.18868,6692.71,5.78395
74.1981,1191.74,1.18952,6685.93,5.78542
74.248,1191.75,1.19035,6679.42,5.78686
74.298,1191.75,1.19119,6672.82,5.78814
74.3481,1191.75,1.19202,6666.12,5.78932
74.3981,1191.75,1.19285,6659.34,5.79037
74.4481,1191.75,1.19368,6652.56,5.79138
74.498,1191.75,1.19452,6645.6,5.79237
74.548,1191.75,1.19535,6638.44,5.7934
74.5981,1191.75,1.19618,6631.46,5.79456
74.6481,1191.75,1.19702,6624.52,5.79572
74.6981,1191.75,1.19785,6617.49,5.79676
74.748,1191.75,1.19868,6610.25,5.79787
74.798,1191.75,1.19951,6602.75,5.79896
74.8481,1191.76,1.20035,6595.22,5.80017
74.8981,1191.76,1.20119,6587.55,5.80162
74.9481,1191.76,1.20202,6579.67,5.80293
74.998,1191.76,1.20284,6572.04,5.80406
75.048,1191.76,1.20368,6564.76,5.80534
75.0981,1191.76,1.20452,6557.61,5.80682
75.1481,1191.76,1.20535,6550.44,5.80829
75.1981,1191.76,1.20619,6543,5.80959
75.248,1191.76,1.20702,6534.81,5.81086
75.298,1191.76,1.20785,6525.53,5.81228
75.3481,1191.76,1.20868,6515.62,5.8137
75.3981,1191.76,1.20951,6505.8,5.8149
75.4481,1191.77,1.21035,6496.08,5.81601
75.498,1191.77,1.21118,6486.29,5.81709
75.548,1191.77,1.21202,6476.53,5.81803
75.5981,1191.77,1.21284,6467.03,5.81898
75.6481,1191.77,1.21368,6457.7,5.82004
75.6981,1191.77,1.21451,6448.17,5.821
75.748,1191.77,1.21534,6438.55,5.82168
75.798,1191.77,1.21618,6429.21,5.82244
75.8481,1191.77,1.21701,6420.51,5.82332
75.8981,1191.77,1.21786,6412.52,5.8242
75.9481,1191.77,1.21869,6404.82,5.82509
75.998,1191.77,1.21951,6397.05,5.82593
76.048,1191.78,1.22035,6389.18,5.82676
76.0981,1191.78,1.22118,6381.13,5.82749
76.1481,1191.78,1.22202,6372.83,5.82819
76.1981,1191.78,1.22285,6364.33,5.82897
76.248,1191.78,1.22369,6355.6,5.82986
76.298,1191.78,1.22452,6346.57,5.83067
76.3481,1191.78,1.22535,6337.23,5.83127
76.3981,1191.78,1.22618,6327.54,5.83183
76.4481,1191.78,1.22702,6317.87,5.83232
76.498,1191.78,1.22785,6308.18,5.83273
76.548,1191.78,1.22868,6297.96,5.83321
76.5981,1191.78,1.22951,6287.29,5.8338
76.6481,1191.79,1.23035,6276.3,5.83443
76.6981,1191.79,1.23119,6264.93,5.83504
76.748,1191.79,1.23202,6253,5.83562
76.798,1191.79,1.23285,6240.65,5.83617
76.8481,1191.79,1.23368,6228.08,5.83668
76.8981,1191.79,1.23452,6214.89,5.83717
76.9481,1191.79,1.23535,6201.02,5.83773
76.998,1191.79,1.23618,6187.15,5.83841
77.048,1191.79,1.23702,6173.05,5.83917
77.0981,1191.79,1.23786,6157.38,5.84
77.1481,1191.79,1.23868,6139.14,5.84098
77.1981,1191.79,1.23951,6118.93,5.84206
77.248,1191.8,1.24035,6098.16,5.8431
77.298,1191.8,1.24118,6076.95,5.84413
77.3481,1191.8,1.24202,6055.97,5.84519
77.3981,1191.8,1.24285,6035.86,5.8462
77.4481,1191.8,1.24369,6016.5,5.8473
77.498,1191.8,1.24452,5998.37,5.84844
77.548,1191.8,1.24536,5981.63,5.8494
77.5981,1191.8,1.24619,5965.01,5.85021
77.6481,1191.8,1.24701,5947.55,5.85104
77.6981,1191.8,1.24785,5928.95,5.85205
77.748,1191.8,1.24868,5909.8,5.85309
77.798,1191.8,1.24951,5891.08,5.85413
77.8481,1191.81,1.25035,5873.32,5.85541
77.8981,1191.81,1.25119,5856.96,5.8567
77.9481,1191.81,1.25202,5841.86,5.85795
77.998,1191.81,1.25285,5827.05,5.85925
78.048,1191.81,1.25368,5812.01,5.86064
78.0981,1191.81,1.25452,5797.02,5.86193
78.1481,1191.81,1.25535,5782.02,5.86308
78.1981,1191.81,1.25618,5767.07,5.86445
78.248,1191.81,1.25702,5752.54,5.86599
78.298,1191.81,1.25785,5738.7,5.86756
78.3481,1191.81,1.25869,5725.5,5.86922
78.3981,1191.81,1.25952,5712.5,5.87092
78.4481,1191.82,1.26035,5699.1,5.87256
78.498,1191.82,1.26118,5685.43,5.87398
78.548,1191.82,1.26202,5671.6,5.87542
78.5981,1191.82,1.26285,5657.46,5.87699
78.6481,1191.82,1.26369,5643.16,5.87869
78.6981,1191.82,1.26451,5628.58,5.88043
78.748,1191.82,1.26536,5613.52,5.88217
78.798,1191.82,1.26618,5598.07,5.8841
78.8481,1191.82,1.26702,5582.44,5.88596
78.8981,1191.82,1.26785,5566.01,5.88768
78.9481,1191.82,1.26868,5548.43,5.88954
78.998,1191.82,1.26951,5530.56,5.89137
79.048,1191.83,1.27035,5513.38,5.89297
79.0981,1191.83,1.27118,5497.17,5.89463
79.1481,1191.83,1.27201,5481.73,5.89646
79.1981,1191.83,1.27286,5466.5,5.89834
79.248,1191.83,1.27367,5450.98,5.9002
79.298,1191.83,1.27452,5434.68,5.90189
79.3481,1191.83,1.27535,5417.72,5.90343
79.3981,1191.83,1.27619,5400.57,5.90509
79.4481,1191.83,1.27701,5383.79,5.90681
79.498,1191.83,1.27785,5368.02,5.90822
79.548,1191.83,1.27868,5352.98,5.90949
79.5981,1191.83,1.27951,5337.39,5.91085
79.6481,1191.84,1.28035,5321.01,5.91219
79.6981,1191.84,1.28119,5304.76,5.91338
79.748,1191.84,1.28202,5288.97,5.91447
79.798,1191.84,1.28284,5273.41,5.91567
79.8481,1191.84,1.28368,5257.78,5.91688
79.8981,1191.84,1.28451,5241.71,5.91799
79.9481,1191.84,1.28535,5224.7,5.91916
79.998,1191.84,1.28619,5206.88,5.92037
80.048,1191.84,1.28701,5188.88,5.92147
80.0981,1191.84,1.28785,5171.46,5.92256
80.1481,1191.84,1.28868,5154.57,5.92373
80.1981,1191.84,1.28951,5137.78,5.92489
80.248,1191.85,1.29035,5121.44,5.92588
80.298,1191.85,1.29118,5105.84,5.92673
80.3481,1191.85,1.29202,5090.97,5.92762
80.3981,1191.85,1.29285,5076.74,5.92853
80.4481,1191.85,1.29368,5062.78,5.92937
80.498,1191.85,1.29451,5048.68,5.93018
80.548,1191.85,1.29535,5034.47,5.93101
80.5981,1191.85,1.29618,5020.59,5.9319
80.6481,1191.85,1.29701,5007.19,5.93276
80.6981,1191.85,1.29785,4994.17,5.93355
80.748,1191.85,1.29869,4981.04,5.93446
80.798,1191.85,1.29952,4967.34,5.93554
80.8481,1191.86,1.30035,4953.18,5.93658
80.8981,1191.86,1.30119,4938.78,5.93745
80.9481,1191.86,1.30201,4923.93,5.93831
80.998,1191.86,1.30285,4908.45,5.93926
81.048,1191.86,1.30368,4892.41,5.94029
81.0981,1191.86,1.30451,4875.24,5.94143
81.1481,1191.86,1.30535,4856.1,5.94253
81.1981,1191.86,1.30618,4835.75,5.94353
81.248,1191.86,1.30702,4815.57,5.94445
81.298,1191.86,1.30785,4795.92,5.9454
81.3481,1191.86,1.30868,4776.26,5.94646
81.3981,1191.86,1.30952,4755.68,5.94763
81.4481,1191.87,1.31035,4734.66,5.94879
81.498,1191.87,1.31118,4714.38,5.94998
81.548,1191.87,1.31202,4694.28,5.95114
81.5981,1191.87,1.31285,4673.26,5.95237
81.6481,1191.87,1.31368,4651.55,5.95392
81.6981,1191.87,1.31452,4629.52,5.95558
81.748,1191.87,1.31535,4607.6,5.95718
81.798,1191.87,1.31619,4586.86,5.95882
81.8481,1191.87,1.31702,4567.57,5.96051
81.8981,1191.87,1.31785,4549.32,5.96201
81.9481,1191.87,1.31868,4531.98,5.96358
81.998,1191.87,1.31952,4514.99,5.96536
82.048,1191.88,1.32035,4497.54,5.96695
82.0981,1191.88,1.32118,4479.65,5.96858
82.1481,1191.88,1.32202,4461.93,5.97055
82.1981,1191.88,1.32285,4444.43,5.97259
82.248,1191.88,1.32368,4426.93,5.9744
82.298,1191.88,1.32452,4409.16,5.97604
82.3481,1191.88,1.32535,4390.32,5.97773
82.3981,1191.88,1.32619,4369.61,5.97939
82.4481,1191.88,1.32702,4346.84,5.98114
82.498,1191.88,1.32785,4323.08,5.98296
82.548,1191.88,1.32868,4299.82,5.98468
82.5981,1191.88,1.32952,4277.48,5.9866
82.6481,1191.89,1.33035,4255.78,5.98841
82.6981,1191.89,1.33118,4234.31,5.99013
82.748,1191.89,1.33202,4212.63,5.992
82.798,1191.89,1.33287,4189.23,5.99387
82.8481,1191.89,1.33368,4163.18,5.99587
82.8981,1191.89,1.33452,4136.16,5.99793
82.9481,1191.89,1.33536,4110.08,5.99978
82.998,1191.89,1.33618,4086.35,6.00153
83.048,1191.89,1.33702,4065.06,6.00327
83.0981,1191.89,1.33785,4045.29,6.00492
83.1481,1191.89,1.33867,4026.24,6.00645
83.1981,1191.89,1.33952,4006.63,6.00786
83.248,1191.9,1.34036,3985.51,6.00922
83.298,1191.9,1.34119,3962.62,6.01054
83.3481,1191.9,1.34202,3938.05,6.01204
83.3981,1191.9,1.34284,3912.64,6.01361
83.4481,1191.9,1.34369,3887.58,6.01494
83.498,1191.9,1.34452,3862.49,6.01627
83.548,1191.9,1.34535,3836.95,6.01763
83.5981,1191.9,1.34618,3811.35,6.01895
83.6481,1191.9,1.34702,3785.94,6.02015
83.6981,1191.9,1.34785,3761.4,6.02116
83.748,1191.9,1.34868,3737.96,6.02213
83.798,1191.9,1.34952,3714.5,6.02318
83.8481,1191.91,1.35035,3689.66,6.02431
83.8981,1191.91,1.35118,3663.58,6.02555
83.9481,1191.91,1.35202,3636.65,6.02678
83.998,1191.91,1.35285,3608.86,6.02796
84.048,1191.91,1.35369,3581.26,6.02922
84.0981,1191.91,1.35452,3553.59,6.03045
84.1481,1191.91,1.35535,3525.59,6.03167
84.1981,1191.91,1.35618,3497.4,6.03286
84.248,1191.91,1.35701,3468.21,6.03395
84.298,1191.91,1.35785,3437.96,6.03509
84.3481,1191.91,1.35869,3407.51,6.03626
84.3981,1191.91,1.35952,3378.1,6.03744
84.4481,1191.92,1.36035,3350.28,6.03874
84.498,1191.92,1.36118,3323.2,6.03999
84.548,1191.92,1.36201,3296.78,6.04118
84.5981,1191.92,1.36284,3271.27,6.04244
84.6481,1191.92,1.36369,3245.18,6.04385
84.6981,1191.92,1.36452,3217.17,6.04554
84.748,1191.92,1.36535,3187.55,6.04738
84.798,1191.92,1.36618,3158.24,6.04909
84.8481,1191.92,1.36701,3130.54,6.05065
84.8981,1191.92,1.36785,3104.09,6.05226
84.9481,1191.92,1.36868,3078.05,6.05401
84.998,1191.92,1.36952,3052.3,6.05566
85.048,1191.93,1.37035,3027.12,6.05725
85.0981,1191.93,1.37118,3002.06,6.05909
85.1481,1191.93,1.37201,2975.25,6.06146
85.1981,1191.93,1.37285,2946.5,6.06413
85.248,1191.93,1.37368,2917.91,6.06671
85.298,1191.93,1.37452,2890.25,6.06914
85.3481,1191.93,1.37535,2863.42,6.07133
85.3981,1191.93,1.37618,2836.69,6.07355
85.4481,1191.93,1.37702,2808.98,6.07584
85.498,1191.93,1.37785,2780.63,6.07804
85.548,1191.93,1.37868,2753.2,6.08026
85.5981,1191.93,1.37952,2726.8,6.08289
85.6481,1191.94,1.38036,2700.56,6.08586
85.6981,1191.94,1.38118,2674.31,6.08892
85.748,1191.94,1.38201,2647.9,6.09178
85.798,1191.94,1.38285,2620.8,6.09447
85.8481,1191.94,1.38369,2592.77,6.09724
85.8981,1191.94,1.38452,2564.41,6.09991
85.9481,1191.94,1.38534,2535.44,6.10194
85.998,1191.94,1.38618,2505.08,6.10355
86.048,1191.94,1.38702,2472.21,6.10527
86.0981,1191.94,1.38785,2439.03,6.10705
86.1481,1191.94,1.38868,2409.3,6.10901
86.1981,1191.94,1.38951,2382.41,6.11083
86.248,1191.95,1.39035,2355.69,6.1122
86.298,1191.95,1.39118,2328.07,6.11342
86.3481,1191.95,1.39201,2301,6.11471
86.3981,1191.95,1.39285,2275.32,6.11613
86.4481,1191.95,1.39369,2250.27,6.11751
86.498,1191.95,1.39452,2223.71,6.11869
86.548,1191.95,1.39535,2194.09,6.1198
86.5981,1191.95,1.39618,2162.02,6.12099
86.6481,1191.95,1.39702,2127.88,6.12226
86.6981,1191.95,1.39784,2092.77,6.12358
86.748,1191.95,1.39868,2056.32,6.12504
86.798,1191.95,1.39952,2018.63,6.12663
86.8481,1191.96,1.40035,1983.75,6.12821
86.8981,1191.96,1.40119,1951.71,6.12972
86.9481,1191.96,1.40202,1918.56,6.13122
86.998,1191.96,1.40284,1884.37,6.13263
87.048,1191.96,1.40368,1851.06,6.13391
87.0981,1191.96,1.40451,1817.15,6.1352
87.1481,1191.96,1.40535,1781.91,6.13648
87.1981,1191.96,1.40618,1748.5,6.13767
87.248,1191.96,1.40702,1717.38,6.13871
87.298,1191.96,1.40785,1684.73,6.13972
87.3481,1191.96,1.40868,1650.88,6.14091
87.3981,1191.96,1.40952,1619.17,6.14216
87.4481,1191.97,1.41035,1590.4,6.14343
87.498,1191.97,1.41118,1563.75,6.14481
87.548,1191.97,1.41202,1538.44,6.14605
87.5981,1191.97,1.41285,1513.74,6.14715
87.6481,1191.97,1.41369,1487.83,6.14843
87.6981,1191.97,1.41452,1459.91,6.14999
87.748,1191.97,1.41535,1431.24,6.15157
87.798,1191.97,1.41618,1401.34,6.15305
87.8481,1191.97,1.41702,1370.71,6.15456
87.8981,1191.97,1.41786,1342.07,6.15624
87.9481,1191.97,1.41868,1314.72,6.15827
87.998,1191.97,1.41952,1287.2,6.16048
88.048,1191.98,1.42035,1259.49,6.16246
88.0981,1191.98,1.42119,1231.24,6.16434
88.1481,1191.98,1.42201,1202.89,6.16624
88.1981,1191.98,1.42285,1177.31,6.1681
88.248,1191.98,1.42368,1155.58,6.16987
88.298,1191.98,1.42452,1135.74,6.17157
88.3481,1191.98,1.42535,1116.12,6.17328
88.3981,1191.98,1.42618,1094.69,6.17494
88.4481,1191.98,1.42702,1071.22,6.17671
88.498,1191.98,1.42785,1045.53,6.17888
88.548,1191.98,1.42869,1017.19,6.18108
88.5981,1191.98,1.42952,988.882,6.183
88.6481,1191.99,1.43035,960.461,6.18488
88.6981,1191.99,1.43119,929.414,6.18714
88.748,1191.99,1.43202,869.312,6.19004
88.798,1191.99,1.43285,598.431,6.20555
88.8481,1191.99,1.43369,377.8,6.21968
88.8981,1191.99,1.43452,387.411,6.21994
88.998,1191.99,1.43618,378.698,6.22007
89.048,1191.99,1.43702,370.383,6.22016
89.0981,1191.99,1.43785,362.507,6.22028
89.1481,1191.99,1.43868,354.968,6.22037
89.1981,1191.99,1.43951,347.746,6.22044
89.248,1192,1.44027,340.784,6.22052
89.298,1192,1.44068,334.497,6.22061
89.3981,1192,1.44074,327.9,6.22079
89.728,1192,1.44074,322.643,6.22114
90.678,1192,1.44074,317.473,6.22148
92.928,1192,1.44074,312.423,6.22045
97.748,1192,1.44074,307.331,6.22217
107.858,1192,1.44074,302.441,6.22557