File: imap_versions/other_machine_outputs_examples/mDB1pct.txt
"Specimen thickness",1.06,"mm"
"Specimen width",6.02,"mm"
"Cross-section",6.3812,"mm²"
"Gage length, standard travel",20,"mm"
"Extensometer",""
"Load cell",""
"Date/Clock time",43447.4,""
"Operator",""
"v1",1,"mm/min"
"v2",1,"mm/min"
"Time","Crosshead absolute","Standard force","Standard travel"
"s","mm","N","mm"
9.49405,-755.377,74.1155,0
9.70405,-755.376,77.6833,0
9.74405,-755.376,82.2415,0
9.77405,-755.375,87.375,0.00019
9.80405,-755.375,93.212,0.0002
9.83405,-755.374,99.2753,0.0002
9.86405,-755.374,104.725,0.0002
9.89405,-755.373,109.476,0.00039
9.92405,-755.373,114.231,0.0004
9.95405,-755.372,119.025,0.00059
9.98405,-755.372,123.83,0.0006
10.0141,-755.371,128.617,0.0006
10.0441,-755.371,133.386,0.0008
10.0741,-755.37,138.197,0.0008
10.1041,-755.37,142.985,0.001
10.1341,-755.369,147.788,0.001
10.1641,-755.369,152.672,0.00119
10.1941,-755.368,157.626,0.0012
10.2241,-755.368,162.666,0.0012
10.2541,-755.367,167.554,0.0014
10.2841,-755.367,172.501,0.0014
10.3141,-755.366,177.368,0.0016
10.3441,-755.366,182.292,0.0016
10.3741,-755.365,187.136,0.0016
10.4041,-755.365,191.964,0.0018
10.4341,-755.364,196.798,0.0018
10.4641,-755.364,201.649,0.002
10.4941,-755.363,206.552,0.002
10.5241,-755.363,211.416,0.002
10.5541,-755.362,216.286,0.0022
10.5841,-755.362,221.207,0.0022
10.6141,-755.361,226.084,0.0024
10.6441,-755.361,230.898,0.0024
10.6741,-755.36,235.672,0.0024
10.7041,-755.36,240.444,0.0026
10.7341,-755.359,244.945,0.0026
10.7641,-755.359,248.745,0.0028
10.8141,-755.358,253.343,0.0028
10.8741,-755.357,257.275,0.003
10.9541,-755.355,260.897,0.003
11.0441,-755.354,264.573,0.003
11.0941,-755.353,269.391,0.003
11.1241,-755.353,273.822,0.0032
11.1541,-755.352,278.967,0.0032
11.1841,-755.352,283.99,0.0032
11.2141,-755.351,289.316,0.0034
11.2441,-755.351,295.732,0.0034
11.2741,-755.35,303.51,0.0036
11.3041,-755.35,312.683,0.0038
11.3341,-755.349,322.298,0.0038
11.3641,-755.349,332.002,0.004
11.3941,-755.348,341.65,0.0042
11.4241,-755.348,351.357,0.0044
11.4541,-755.347,361.096,0.00459
11.4841,-755.347,370.974,0.0046
11.5141,-755.346,380.839,0.0048
11.5441,-755.346,390.853,0.005
11.5741,-755.345,400.788,0.0052
11.6041,-755.345,410.859,0.0052
11.6341,-755.344,420.859,0.0054
11.6641,-755.344,430.966,0.0056
11.6941,-755.343,441.124,0.0058
11.7241,-755.343,451.268,0.00599
11.7541,-755.342,461.357,0.006
11.7841,-755.342,471.369,0.0062
11.8141,-755.341,481.401,0.0064
11.8441,-755.341,491.415,0.0066
11.8741,-755.34,501.417,0.0068
11.9041,-755.34,511.395,0.00699
11.9341,-755.339,521.342,0.007
11.9641,-755.339,531.36,0.0072
11.9941,-755.338,541.327,0.0074
12.0241,-755.338,551.231,0.0076
12.0541,-755.337,561.133,0.0076
12.0841,-755.337,570.995,0.0078
12.1141,-755.336,580.938,0.008
12.1441,-755.336,590.892,0.0082
12.1741,-755.335,600.831,0.00839
12.2041,-755.335,610.735,0.0084
12.2341,-755.334,620.606,0.0086
12.2641,-755.334,630.521,0.0088
12.2941,-755.333,640.466,0.0088
12.3241,-755.333,650.478,0.009
12.3541,-755.332,660.547,0.0092
12.3841,-755.332,670.606,0.0094
12.4141,-755.331,680.739,0.0096
12.4441,-755.331,690.85,0.0096
12.4741,-755.33,700.969,0.0098
12.5041,-755.33,711.107,0.0098
12.5341,-755.329,721.207,0.01
12.5641,-755.329,731.298,0.0102
12.5941,-755.328,741.357,0.0104
12.6241,-755.328,751.323,0.0104
12.6541,-755.327,761.361,0.0106
12.6841,-755.327,771.293,0.0108
12.7141,-755.326,781.134,0.011
12.7441,-755.326,791,0.011
12.7741,-755.325,800.866,0.0112
12.8041,-755.325,810.868,0.0114
12.8341,-755.324,820.839,0.0114
12.8641,-755.324,830.72,0.0116
12.8941,-755.323,840.544,0.0118
12.9241,-755.323,850.363,0.012
12.9541,-755.322,860.193,0.0122
12.9841,-755.322,870.056,0.01239
13.0141,-755.321,879.966,0.0124
13.0441,-755.321,889.849,0.0126
13.0741,-755.32,899.778,0.01279
13.1041,-755.32,909.761,0.0128
13.1341,-755.319,919.782,0.013
13.1641,-755.319,929.812,0.0132
13.1941,-755.318,939.848,0.0134
13.2241,-755.318,949.911,0.0134
13.2541,-755.317,959.952,0.0136
13.2841,-755.317,969.96,0.0138
13.3141,-755.316,980.023,0.0138
13.3441,-755.316,990.055,0.014
13.3741,-755.315,1000.09,0.0142
13.4041,-755.315,1010.08,0.0142
13.4341,-755.314,1019.93,0.01441
13.4641,-755.314,1029.84,0.0146
13.4941,-755.313,1039.74,0.0148
13.5241,-755.313,1049.67,0.015
13.5541,-755.312,1059.63,0.015
13.5841,-755.312,1069.54,0.0152
13.6141,-755.311,1079.5,0.0154
13.6441,-755.311,1089.35,0.0154
13.6741,-755.31,1099.08,0.0156
13.7041,-755.31,1108.77,0.0158
13.7341,-755.309,1118.49,0.0158
13.7641,-755.309,1128.28,0.016
13.7941,-755.308,1138.17,0.0162
13.8241,-755.308,1148.02,0.0164
13.8541,-755.307,1157.93,0.01659
13.8841,-755.307,1167.82,0.0166
13.9141,-755.306,1177.79,0.0168
13.9441,-755.306,1187.77,0.0168
13.9741,-755.305,1197.74,0.017
14.0041,-755.305,1207.7,0.0172
14.0341,-755.304,1217.68,0.0172
14.0641,-755.304,1227.6,0.0174
14.0941,-755.303,1237.55,0.0176
14.1241,-755.303,1247.42,0.0178
14.1541,-755.302,1257.26,0.018
14.1841,-755.302,1267.08,0.018
14.2141,-755.301,1276.79,0.01819
14.2441,-755.301,1286.65,0.0182
14.2741,-755.3,1296.44,0.0184
14.3041,-755.3,1306.29,0.0186
14.3341,-755.299,1316.05,0.0186
14.3641,-755.299,1325.79,0.0188
14.3941,-755.298,1335.46,0.019
14.4241,-755.298,1345.15,0.0192
14.4541,-755.297,1354.8,0.0192
14.4841,-755.297,1364.35,0.0194
14.5141,-755.296,1373.94,0.01959
14.5441,-755.296,1383.63,0.0196
14.5741,-755.295,1393.34,0.0198
14.6041,-755.295,1403.04,0.0198
14.6341,-755.294,1412.73,0.02
14.6641,-755.294,1422.39,0.0202
14.6941,-755.293,1431.99,0.0204
14.7241,-755.293,1441.68,0.0206
14.7541,-755.292,1451.36,0.0206
14.7841,-755.292,1461.11,0.0208
14.8141,-755.291,1470.85,0.021
14.8441,-755.291,1480.53,0.0212
14.8741,-755.29,1490.14,0.02139
14.9041,-755.29,1499.72,0.0214
14.9341,-755.289,1509.17,0.0216
14.9641,-755.289,1518.71,0.0216
14.9941,-755.288,1528.13,0.0218
15.0241,-755.288,1537.61,0.022
15.0541,-755.287,1547.06,0.0222
15.0841,-755.287,1556.49,0.0222
15.1141,-755.286,1565.79,0.0224
15.1441,-755.286,1575.04,0.0226
15.1741,-755.285,1584.17,0.0226
15.2041,-755.285,1593.22,0.0228
15.2341,-755.284,1602.2,0.0228
15.2641,-755.284,1611.13,0.023
15.2941,-755.283,1620.08,0.0232
15.3241,-755.283,1628.95,0.0232
15.3541,-755.282,1637.79,0.0234
15.3841,-755.282,1646.57,0.0236
15.4141,-755.281,1655.39,0.02379
15.4441,-755.281,1664.04,0.0238
15.4741,-755.28,1672.61,0.024
15.5041,-755.28,1681.11,0.024
15.5341,-755.279,1689.44,0.0242
15.5641,-755.279,1697.71,0.0244
15.5941,-755.278,1705.84,0.0244
15.6241,-755.278,1713.8,0.0246
15.6541,-755.277,1721.6,0.0248
15.6841,-755.277,1729.19,0.0248
15.7141,-755.276,1736.69,0.025
15.7441,-755.276,1743.96,0.025
15.7741,-755.275,1751.13,0.0252
15.8041,-755.275,1758.21,0.0252
15.8341,-755.274,1765.27,0.0252
15.8641,-755.274,1772.28,0.0254
15.8941,-755.273,1779.28,0.02541
15.9241,-755.273,1786.18,0.0256
15.9541,-755.272,1793.05,0.0256
15.9841,-755.272,1799.89,0.0258
16.0141,-755.271,1806.65,0.0258
16.0441,-755.271,1813.42,0.0258
16.0741,-755.27,1820.19,0.026
16.1041,-755.27,1826.98,0.026
16.1341,-755.269,1833.87,0.0262
16.1641,-755.269,1840.8,0.0264
16.1941,-755.268,1847.78,0.0264
16.2241,-755.268,1854.82,0.0266
16.2541,-755.267,1861.95,0.0266
16.2841,-755.267,1869.02,0.0266
16.3141,-755.266,1876.09,0.0268
16.3441,-755.266,1883.1,0.0268
16.3741,-755.265,1890.07,0.027
16.4041,-755.265,1896.95,0.02701
16.4341,-755.264,1903.83,0.0272
16.4641,-755.264,1910.64,0.0274
16.4941,-755.263,1917.52,0.0274
16.5241,-755.263,1924.38,0.0274
16.5541,-755.262,1931.26,0.0276
16.5841,-755.262,1938.08,0.0276
16.6141,-755.261,1944.91,0.0278
16.6441,-755.261,1951.7,0.0278
16.6741,-755.26,1958.48,0.028
16.7041,-755.26,1965.2,0.028
16.7341,-755.259,1971.97,0.0282
16.7641,-755.259,1978.72,0.0282
16.7941,-755.258,1985.53,0.0284
16.8241,-755.258,1992.28,0.0286
16.8541,-755.257,1999.04,0.0286
16.8841,-755.257,2005.66,0.0288
16.9141,-755.256,2012.32,0.0288
16.9441,-755.256,2018.94,0.029
16.9741,-755.255,2025.69,0.029
17.0041,-755.255,2032.47,0.029
17.0341,-755.254,2039.24,0.0292
17.0641,-755.254,2045.95,0.0292
17.0941,-755.253,2052.54,0.0294
17.1241,-755.253,2059.07,0.0294
17.1541,-755.252,2065.39,0.0296
17.1841,-755.252,2071.67,0.0296
17.2141,-755.251,2077.88,0.0298
17.2441,-755.251,2084.01,0.0298
17.2741,-755.25,2090.09,0.03
17.3041,-755.25,2096.15,0.03
17.3341,-755.249,2102.2,0.03
17.3641,-755.249,2108.21,0.0302
17.3941,-755.248,2114.26,0.0302
17.4241,-755.248,2120.28,0.0304
17.4541,-755.247,2126.28,0.0304
17.4841,-755.247,2132.26,0.0306
17.5141,-755.246,2138.22,0.0306
17.5441,-755.246,2144.23,0.0306
17.5741,-755.245,2150.31,0.0308
17.6041,-755.245,2156.42,0.0308
17.6341,-755.244,2162.51,0.031
17.6641,-755.244,2168.64,0.031
17.6941,-755.243,2174.85,0.0312
17.7241,-755.243,2181.06,0.0312
17.7541,-755.242,2187.29,0.0314
17.7841,-755.242,2193.56,0.0314
17.8141,-755.241,2199.88,0.0314
17.8441,-755.241,2206.17,0.0316
17.8741,-755.24,2212.49,0.0316
17.9041,-755.24,2218.73,0.0318
17.9341,-755.239,2224.94,0.0318
17.9641,-755.239,2231.08,0.032
17.9941,-755.238,2237.16,0.032
18.0241,-755.238,2243.29,0.03201
18.0541,-755.237,2249.4,0.0322
18.0841,-755.237,2255.52,0.0322
18.1141,-755.236,2261.58,0.0324
18.1441,-755.236,2267.64,0.0324
18.1741,-755.235,2273.75,0.0326
18.2041,-755.235,2279.83,0.0326
18.2341,-755.234,2285.94,0.03279
18.2641,-755.234,2291.98,0.0328
18.2941,-755.233,2298.04,0.0328
18.3241,-755.233,2304.07,0.033
18.3541,-755.232,2310.11,0.033
18.3841,-755.232,2316.21,0.0332
18.4141,-755.231,2322.31,0.0332
18.4441,-755.231,2328.45,0.0332
18.4741,-755.23,2334.57,0.0334
18.5041,-755.23,2340.72,0.0334
18.5341,-755.229,2346.8,0.0336
18.5641,-755.229,2352.91,0.0336
18.5941,-755.228,2359.02,0.0338
18.6241,-755.228,2365.11,0.0338
18.6541,-755.227,2371.14,0.0338
18.6841,-755.227,2377.13,0.034
18.7141,-755.226,2383.08,0.034
18.7441,-755.226,2388.93,0.0342
18.7741,-755.225,2394.76,0.0342
18.8041,-755.225,2400.56,0.0344
18.8341,-755.224,2406.49,0.0344
18.8641,-755.224,2412.43,0.03459
18.8941,-755.223,2418.29,0.0346
18.9241,-755.223,2424.17,0.0346
18.9541,-755.222,2429.93,0.0346
18.9841,-755.222,2435.76,0.0348
19.0141,-755.221,2441.61,0.0348
19.0441,-755.221,2447.37,0.035
19.0741,-755.22,2453.15,0.035
19.1041,-755.22,2458.91,0.0352
19.1341,-755.219,2464.71,0.0352
19.1641,-755.219,2470.57,0.0352
19.1941,-755.218,2476.42,0.0354
19.2241,-755.218,2482.19,0.0354
19.2541,-755.217,2488.1,0.0354
19.2841,-755.217,2493.98,0.0356
19.3141,-755.216,2499.91,0.0358
19.3441,-755.216,2505.74,0.0358
19.3741,-755.215,2511.53,0.0358
19.4041,-755.215,2517.38,0.03599
19.4341,-755.214,2523.18,0.036
19.4641,-755.214,2528.95,0.036
19.4941,-755.213,2534.68,0.0362
19.5241,-755.213,2540.37,0.0362
19.5541,-755.212,2546.04,0.0364
19.5841,-755.212,2551.71,0.0364
19.6141,-755.211,2557.42,0.0366
19.6441,-755.211,2563.15,0.0366
19.6741,-755.21,2568.85,0.0366
19.7041,-755.21,2574.52,0.0368
19.7341,-755.209,2580.1,0.0368
19.7641,-755.209,2585.65,0.0368
19.7941,-755.208,2591.19,0.037
19.8241,-755.208,2596.79,0.037
19.8541,-755.207,2602.38,0.0372
19.8841,-755.207,2607.92,0.0372
19.9141,-755.206,2613.53,0.0372
19.9441,-755.206,2619.15,0.0374
19.9741,-755.205,2624.88,0.0374
20.0041,-755.205,2630.55,0.0376
20.0341,-755.204,2636.26,0.0376
20.0641,-755.204,2641.98,0.0378
20.0941,-755.203,2647.63,0.0378
20.1241,-755.203,2653.22,0.0378
20.1541,-755.202,2658.71,0.038
20.1841,-755.202,2664.18,0.038
20.2141,-755.201,2669.61,0.0382
20.2441,-755.201,2675.01,0.0382
20.2741,-755.2,2680.5,0.0382
20.3041,-755.2,2685.88,0.0384
20.3341,-755.199,2691.27,0.0384
20.3641,-755.199,2696.57,0.0386
20.3941,-755.198,2701.8,0.0386
20.4241,-755.198,2707.02,0.0386
20.4541,-755.197,2712.07,0.0388
20.4841,-755.197,2717.05,0.0388
20.5141,-755.196,2721.96,0.039
20.5441,-755.196,2726.65,0.039
20.5741,-755.195,2731.02,0.039
20.6141,-755.194,2734.9,0.0392
20.6741,-755.193,2738.25,0.0392
20.7141,-755.193,2742.15,0.0392
20.7441,-755.192,2746.61,0.0392
20.7741,-755.192,2751.8,0.0394
20.8041,-755.191,2757.33,0.0394
20.8341,-755.191,2763.06,0.0396
20.8641,-755.19,2768.82,0.0396
20.8941,-755.19,2774.63,0.0398
20.9241,-755.189,2780.38,0.0398
20.9541,-755.189,2786.03,0.04
20.9841,-755.188,2791.62,0.04
21.0141,-755.188,2797.06,0.04
21.0441,-755.187,2802.41,0.0402
21.0741,-755.187,2807.69,0.0402
21.1041,-755.186,2812.88,0.0404
21.1341,-755.186,2817.95,0.0404
21.1641,-755.185,2822.95,0.04059
21.1941,-755.185,2827.88,0.0406
21.2241,-755.184,2832.78,0.0406
21.2541,-755.184,2837.62,0.0408
21.2841,-755.183,2842.41,0.0408
21.3141,-755.183,2847.24,0.0408
21.3441,-755.182,2852.09,0.041
21.3741,-755.182,2856.97,0.041
21.4041,-755.181,2861.78,0.04101
21.4341,-755.181,2866.61,0.0412
21.4641,-755.18,2871.49,0.0412
21.4941,-755.18,2876.36,0.0414
21.5241,-755.179,2881.19,0.0414
21.5541,-755.179,2886,0.0416
21.5841,-755.178,2890.88,0.0416
21.6141,-755.178,2895.7,0.0416
21.6441,-755.177,2900.48,0.0418
21.6741,-755.177,2905.28,0.0418
21.7041,-755.176,2909.98,0.042
21.7341,-755.176,2914.68,0.042
21.7641,-755.175,2919.3,0.042
21.7941,-755.175,2923.84,0.0422
21.8241,-755.174,2928.38,0.0422
21.8541,-755.174,2932.95,0.0424
21.8841,-755.173,2937.57,0.0424
21.9141,-755.173,2942.16,0.04259
21.9441,-755.172,2946.8,0.0426
21.9741,-755.172,2951.31,0.0426
22.0041,-755.171,2955.83,0.0428
22.0341,-755.171,2960.29,0.0428
22.0641,-755.17,2964.73,0.0428
22.0941,-755.17,2969.21,0.043
22.1241,-755.169,2973.62,0.043
22.1541,-755.169,2978.08,0.0432
22.1841,-755.168,2982.57,0.0432
22.2141,-755.168,2987.08,0.0432
22.2441,-755.167,2991.6,0.0434
22.2741,-755.167,2996.15,0.0434
22.3041,-755.166,3000.76,0.0434
22.3341,-755.166,3005.32,0.0436
22.3641,-755.165,3009.92,0.0436
22.3941,-755.165,3014.48,0.0438
22.4241,-755.164,3018.96,0.0438
22.4541,-755.164,3023.43,0.04399
22.4841,-755.163,3027.75,0.044
22.5141,-755.163,3032.01,0.044
22.5441,-755.162,3036.19,0.044
22.5741,-755.162,3040.36,0.0442
22.6041,-755.161,3044.57,0.0442
22.6341,-755.161,3048.81,0.0444
22.6641,-755.16,3053.01,0.0444
22.6941,-755.16,3057.21,0.0444
22.7241,-755.159,3061.44,0.0446
22.7541,-755.159,3065.62,0.0446
22.7841,-755.158,3069.78,0.04479
22.8141,-755.158,3073.87,0.0448
22.8441,-755.157,3077.94,0.0448
22.8741,-755.157,3082.07,0.045
22.9041,-755.156,3086.19,0.045
22.9341,-755.156,3090.28,0.045
22.9641,-755.155,3094.39,0.0452
22.9941,-755.155,3098.46,0.0452
23.0241,-755.154,3102.53,0.0454
23.0541,-755.154,3106.58,0.0454
23.0841,-755.153,3110.66,0.0454
23.1141,-755.153,3114.81,0.0456
23.1441,-755.152,3118.93,0.0456
23.1741,-755.152,3122.98,0.0458
23.2041,-755.151,3126.99,0.0458
23.2341,-755.151,3130.97,0.0458
23.2641,-755.15,3134.98,0.046
23.2941,-755.15,3138.9,0.046
23.3241,-755.149,3142.86,0.0462
23.3541,-755.149,3146.7,0.0462
23.3841,-755.148,3150.6,0.0462
23.4141,-755.148,3154.42,0.0464
23.4441,-755.147,3158.32,0.0464
23.4741,-755.147,3162.15,0.04659
23.5041,-755.146,3165.9,0.0466
23.5341,-755.146,3169.63,0.0466
23.5641,-755.145,3173.32,0.0468
23.5941,-755.145,3177.03,0.0468
23.6241,-755.144,3180.71,0.047
23.6541,-755.144,3184.41,0.047
23.6841,-755.143,3188.07,0.047
23.7141,-755.143,3191.8,0.0472
23.7441,-755.142,3195.49,0.0472
23.7741,-755.142,3199.23,0.0474
23.8041,-755.141,3202.89,0.0474
23.8341,-755.141,3206.51,0.0476
23.8641,-755.14,3210.19,0.0476
23.8941,-755.14,3213.82,0.0478
23.9241,-755.139,3217.47,0.0478
23.9541,-755.139,3221.03,0.0478
23.9841,-755.138,3224.55,0.048
24.0141,-755.138,3227.93,0.048
24.0441,-755.137,3231.36,0.0482
24.0741,-755.137,3234.69,0.0482
24.1041,-755.136,3238.02,0.0484
24.1341,-755.136,3241.3,0.0484
24.1641,-755.135,3244.6,0.0486
24.1941,-755.135,3247.82,0.0486
24.2241,-755.134,3251.03,0.0488
24.2541,-755.134,3254.13,0.0488
24.2841,-755.133,3257.22,0.049
24.3141,-755.133,3260.31,0.049
24.3441,-755.132,3263.39,0.0492
24.3741,-755.132,3266.49,0.0492
24.4041,-755.131,3269.56,0.0494
24.4341,-755.131,3272.64,0.0494
24.4741,-755.13,3276.66,0.0496
24.5241,-755.129,3281.65,0.0498
24.5541,-755.129,3284.69,0.0498
24.6041,-755.128,3289.64,0.05
24.6541,-755.127,3294.52,0.0502
24.7141,-755.126,3300.17,0.0504
24.7741,-755.125,3305.7,0.0506
24.8341,-755.124,3310.98,0.051
24.8941,-755.123,3316.09,0.0512
24.9541,-755.122,3321.19,0.0514
25.0141,-755.121,3326,0.0516
25.0741,-755.12,3330.47,0.052
25.1341,-755.119,3335.01,0.0522
25.1941,-755.118,3339.44,0.0526
25.2541,-755.117,3343.69,0.0528
25.3141,-755.116,3347.75,0.0532
25.3741,-755.115,3351.7,0.0534
25.4341,-755.114,3355.34,0.0538
25.4941,-755.113,3358.6,0.0542
25.5641,-755.112,3362.1,0.0546
25.6541,-755.11,3366.22,0.055
25.7441,-755.109,3370,0.0556
25.8541,-755.107,3373.68,0.0564
25.9741,-755.105,3377.12,0.0572
26.1141,-755.103,3380.5,0.0582
26.3241,-755.099,3383.62,0.0598
27.6241,-755.078,3386.69,0.0716
29.1941,-755.051,3389.74,0.09039
29.8841,-755.04,3392.82,0.0994
30.4141,-755.031,3395.94,0.106
30.7741,-755.025,3399.05,0.1108
31.3041,-755.016,3402.11,0.1174
31.7341,-755.009,3405.25,0.1232
32.2341,-755.001,3408.37,0.1298
32.8641,-754.99,3411.44,0.138
33.3741,-754.982,3414.52,0.1448
33.9641,-754.972,3417.61,0.1526
34.4741,-754.963,3420.76,0.159
34.9341,-754.956,3423.8,0.1648
35.2941,-754.95,3426.89,0.1694
35.7141,-754.943,3429.98,0.1744
36.0241,-754.938,3433.08,0.1782
36.3741,-754.932,3436.19,0.1824
36.7141,-754.926,3439.38,0.1864
37.0041,-754.921,3442.49,0.19
37.3541,-754.915,3445.56,0.19419
37.5941,-754.911,3448.67,0.1972
37.9241,-754.906,3451.95,0.201
38.2441,-754.901,3455.14,0.20461
38.5241,-754.896,3458.33,0.20799
38.8441,-754.891,3461.55,0.2116
39.0941,-754.886,3464.78,0.2144
39.4041,-754.881,3468.01,0.2178
39.6941,-754.876,3471.09,0.2212
39.9241,-754.873,3474.41,0.2238
40.2241,-754.868,3477.58,0.227
40.5241,-754.863,3480.66,0.2302
40.7741,-754.858,3483.93,0.2332
41.0941,-754.853,3487.07,0.2366
41.3441,-754.849,3490.33,0.2394
41.6241,-754.844,3493.46,0.2424
41.9241,-754.839,3496.76,0.2456
42.1641,-754.835,3499.88,0.2482
42.4641,-754.83,3503.04,0.2514
42.7441,-754.826,3506.17,0.2542
42.9741,-754.822,3509.28,0.2568
43.2841,-754.817,3512.52,0.2598
43.5641,-754.812,3515.68,0.2626
43.7941,-754.808,3518.78,0.2652
44.1241,-754.803,3521.98,0.2686
44.3741,-754.798,3525.36,0.2712
44.6641,-754.794,3528.47,0.2742
44.9641,-754.789,3531.56,0.2774
45.1941,-754.785,3534.84,0.2798
45.4941,-754.78,3538.04,0.283
45.7941,-754.775,3541.24,0.2862
46.0341,-754.771,3544.44,0.2888
46.3441,-754.766,3547.6,0.292
46.6141,-754.761,3550.76,0.295
46.8541,-754.757,3553.9,0.29759
47.1841,-754.752,3557.16,0.301
47.4441,-754.747,3560.46,0.3038
47.7241,-754.743,3563.62,0.3068
48.0341,-754.737,3566.84,0.31019
48.2741,-754.733,3570.11,0.3128
48.5841,-754.728,3573.26,0.316
48.8541,-754.724,3576.34,0.319
49.0941,-754.72,3579.44,0.3216
49.4241,-754.714,3582.57,0.3252
49.6841,-754.71,3585.74,0.328
49.9641,-754.705,3588.87,0.331
50.2741,-754.7,3591.99,0.33439
50.5141,-754.696,3595.23,0.337
50.8241,-754.691,3598.51,0.3402
51.1341,-754.686,3601.72,0.3436
51.3941,-754.681,3604.96,0.3464
51.7141,-754.676,3608.06,0.3498
51.9841,-754.672,3611.26,0.3528
52.3141,-754.666,3614.5,0.3562
52.6641,-754.66,3617.67,0.3598
53.1241,-754.653,3620.74,0.3644
53.4141,-754.648,3624.01,0.3672
53.6241,-754.644,3627.15,0.3694
53.9041,-754.64,3630.24,0.3722
54.1841,-754.635,3633.34,0.375
54.4341,-754.631,3636.55,0.3776
54.7741,-754.625,3639.75,0.3812
55.0441,-754.621,3642.93,0.384
55.3341,-754.616,3646.09,0.387
55.6441,-754.611,3649.13,0.3902
55.8941,-754.606,3652.36,0.3928
56.2141,-754.601,3655.4,0.3962
56.5041,-754.596,3658.55,0.3992
56.7941,-754.591,3661.78,0.4022
57.1541,-754.585,3664.92,0.406
57.3941,-754.581,3668.13,0.4084
57.7241,-754.576,3671.35,0.4118
58.0241,-754.571,3674.55,0.4148
58.3641,-754.565,3677.8,0.4182
58.7041,-754.56,3680.94,0.4216
58.9641,-754.555,3684.16,0.4242
59.3041,-754.55,3687.27,0.4274
59.5941,-754.545,3690.47,0.43039
59.8941,-754.54,3693.64,0.4334
60.2241,-754.534,3696.82,0.4366
60.4941,-754.53,3700,0.4392
60.8541,-754.524,3703.17,0.4428
61.1341,-754.519,3706.46,0.4456
61.4241,-754.514,3707.06,0.4484
61.4541,-754.514,3702.43,0.44879
61.4841,-754.515,3695.2,0.4488
61.5141,-754.515,3686.63,0.4488
61.5441,-754.516,3678.32,0.4488
61.5741,-754.516,3670.52,0.4488
61.6041,-754.517,3663.24,0.4488
61.6341,-754.517,3656.38,0.4488
61.6641,-754.518,3649.96,0.4488
61.6941,-754.518,3643.85,0.4488
61.7241,-754.519,3638,0.4488
61.7541,-754.519,3632.37,0.4488
61.7841,-754.52,3626.54,0.4488
61.8141,-754.52,3619.64,0.44861
61.8441,-754.521,3611.6,0.4486
61.8741,-754.521,3602.64,0.4484
61.9041,-754.522,3593.62,0.4484
61.9341,-754.522,3584.75,0.4482
61.9641,-754.523,3575.95,0.448
61.9941,-754.523,3567.21,0.4478
62.0241,-754.524,3558.58,0.4478
62.0541,-754.524,3549.89,0.4476
62.0841,-754.525,3541.29,0.4474
62.1141,-754.525,3532.65,0.4472
62.1441,-754.526,3524.01,0.4472
62.1741,-754.526,3515.27,0.447
62.2041,-754.527,3506.53,0.447
62.2341,-754.527,3497.69,0.4468
62.2641,-754.528,3488.81,0.4466
62.2941,-754.528,3479.74,0.4464
62.3241,-754.529,3470.72,0.4464
62.3541,-754.529,3461.88,0.4462
62.3841,-754.53,3453.22,0.446
62.4141,-754.53,3444.79,0.446
62.4441,-754.531,3436.38,0.4458
62.4741,-754.531,3428.11,0.4458
62.5041,-754.532,3419.99,0.4456
62.5341,-754.532,3412.23,0.4454
62.5641,-754.533,3404.98,0.4454
62.5941,-754.533,3398.17,0.4452
62.6241,-754.534,3391.73,0.445
62.6541,-754.534,3385.6,0.445
62.6841,-754.535,3379.77,0.44481
62.7141,-754.535,3374.2,0.4448
62.7441,-754.536,3368.84,0.4448
62.7741,-754.536,3363.66,0.4446
62.8041,-754.537,3358.76,0.4446
62.8341,-754.537,3353.9,0.4444
62.8641,-754.538,3349.08,0.4444
62.8941,-754.538,3344.28,0.4442
62.9241,-754.539,3339.53,0.4442
62.9541,-754.539,3334.8,0.444
62.9841,-754.54,3330.12,0.444
63.0141,-754.54,3325.45,0.444
63.0441,-754.541,3320.83,0.4438
63.0741,-754.541,3316.26,0.4438
63.1041,-754.542,3311.75,0.4436
63.1341,-754.542,3307.3,0.4436
63.1641,-754.543,3302.81,0.4436
63.1941,-754.543,3298.43,0.4434
63.2241,-754.544,3294.01,0.4434
63.2541,-754.544,3289.57,0.4434
63.2841,-754.545,3285.09,0.4432
63.3141,-754.545,3280.65,0.4432
63.3441,-754.546,3276.3,0.443
63.3741,-754.546,3271.99,0.443
63.4041,-754.547,3267.68,0.443
63.4341,-754.547,3263.37,0.4428
63.4641,-754.548,3259.06,0.4428
63.4941,-754.548,3254.78,0.4426
63.5241,-754.549,3250.59,0.4426
63.5541,-754.549,3246.33,0.4426
63.5841,-754.55,3242.11,0.4424
63.6141,-754.55,3237.93,0.4424
63.6441,-754.551,3233.7,0.44221
63.6741,-754.551,3229.5,0.4422
63.7041,-754.552,3225.3,0.4422
63.7341,-754.552,3221.11,0.442
63.7641,-754.553,3216.93,0.442
63.7941,-754.553,3212.71,0.4418
63.8241,-754.554,3208.54,0.4418
63.8541,-754.554,3204.38,0.4418
63.8841,-754.555,3200.22,0.4416
63.9141,-754.555,3196.08,0.4416
63.9441,-754.556,3191.85,0.4416
63.9741,-754.556,3187.01,0.4414
64.0041,-754.557,3181.02,0.4414
64.0341,-754.557,3173.86,0.4412
64.0641,-754.558,3165.93,0.4412
64.0941,-754.558,3157.94,0.441
64.1241,-754.559,3150.1,0.4408
64.1541,-754.559,3142.38,0.4408
64.1841,-754.56,3134.7,0.4406
64.2141,-754.56,3127.16,0.44041
64.2441,-754.561,3119.6,0.4404
64.2741,-754.561,3112.11,0.4402
64.3041,-754.562,3104.51,0.44
64.3341,-754.562,3096.83,0.44
64.3641,-754.563,3089.15,0.4398
64.3941,-754.563,3081.52,0.43979
64.4241,-754.564,3074.17,0.4396
64.4541,-754.564,3067.16,0.4394
64.4841,-754.565,3060.72,0.4394
64.5141,-754.565,3054.56,0.4392
64.5441,-754.566,3048.19,0.4392
64.5741,-754.566,3041.42,0.439
64.6041,-754.567,3033.95,0.4388
64.6341,-754.567,3026.07,0.4388
64.6641,-754.568,3018.02,0.4386
64.6941,-754.568,3009.89,0.4384
64.7241,-754.569,3001.8,0.4384
64.7541,-754.569,2993.61,0.4382
64.7841,-754.57,2985.42,0.438
64.8141,-754.57,2977.18,0.43781
64.8441,-754.571,2968.94,0.4378
64.8741,-754.571,2960.72,0.4376
64.9041,-754.572,2952.56,0.4374
64.9341,-754.572,2944.55,0.4374
64.9641,-754.573,2936.53,0.4372
64.9941,-754.573,2928.52,0.437
65.0241,-754.574,2920.48,0.437
65.0541,-754.574,2912.46,0.4368
65.0841,-754.575,2904.42,0.4366
65.1141,-754.575,2896.36,0.4366
65.1441,-754.576,2888.33,0.4364
65.1741,-754.576,2880.29,0.4362
65.2041,-754.577,2872.33,0.43601
65.2341,-754.577,2864.22,0.436
65.2641,-754.578,2856.1,0.4358
65.2941,-754.578,2847.99,0.4356
65.3241,-754.579,2839.91,0.43541
65.3541,-754.579,2831.82,0.4354
65.3841,-754.58,2823.78,0.4352
65.4141,-754.58,2815.72,0.4352
65.4441,-754.581,2807.61,0.435
65.4741,-754.581,2799.46,0.4348
65.5041,-754.582,2791.26,0.4346
65.5341,-754.582,2783.13,0.4346
65.5641,-754.583,2774.96,0.4344
65.5941,-754.583,2766.78,0.4342
65.6241,-754.584,2758.55,0.4342
65.6541,-754.584,2750.35,0.434
65.6841,-754.585,2742.25,0.4338
65.7141,-754.585,2734.23,0.4336
65.7441,-754.586,2726.28,0.4336
65.7741,-754.586,2718.35,0.4334
65.8041,-754.587,2710.58,0.4332
65.8341,-754.587,2702.69,0.4332
65.8641,-754.588,2694.83,0.433
65.8941,-754.588,2686.9,0.4328
65.9241,-754.589,2678.95,0.4328
65.9541,-754.589,2670.97,0.4326
65.9841,-754.59,2662.96,0.4324
66.0141,-754.59,2654.92,0.4322
66.0441,-754.591,2646.85,0.4322
66.0741,-754.591,2638.84,0.432
66.1041,-754.592,2630.91,0.4318
66.1341,-754.592,2622.92,0.4316
66.1641,-754.593,2614.99,0.4316
66.1941,-754.593,2607.02,0.4314
66.2241,-754.594,2598.99,0.4312
66.2541,-754.594,2590.94,0.4312
66.2841,-754.595,2582.85,0.431
66.3141,-754.595,2574.72,0.4308
66.3441,-754.596,2566.64,0.4308
66.3741,-754.596,2558.61,0.4306
66.4041,-754.597,2550.53,0.4304
66.4341,-754.597,2542.52,0.4302
66.4641,-754.598,2534.58,0.43
66.4941,-754.598,2526.66,0.43
66.5241,-754.599,2518.84,0.4298
66.5541,-754.599,2510.95,0.4298
66.5841,-754.6,2503.12,0.4296
66.6141,-754.6,2495.31,0.4294
66.6441,-754.601,2487.51,0.4292
66.6741,-754.601,2479.69,0.4292
66.7041,-754.602,2471.86,0.429
66.7341,-754.602,2463.99,0.4288
66.7641,-754.603,2456.09,0.4286
66.7941,-754.603,2448.27,0.4286
66.8241,-754.604,2440.33,0.4284
66.8541,-754.604,2432.43,0.4282
66.8841,-754.605,2424.5,0.428
66.9141,-754.605,2416.54,0.428
66.9441,-754.606,2408.67,0.4278
66.9741,-754.606,2400.77,0.4276
67.0041,-754.607,2392.95,0.4276
67.0341,-754.607,2385.14,0.4274
67.0641,-754.608,2377.29,0.4272
67.0941,-754.608,2369.32,0.427
67.1241,-754.609,2361.45,0.42681
67.1541,-754.609,2353.52,0.4268
67.1841,-754.61,2345.64,0.4266
67.2141,-754.61,2337.8,0.4264
67.2441,-754.611,2329.96,0.42621
67.2741,-754.611,2322.25,0.4262
67.3041,-754.612,2314.49,0.426
67.3341,-754.612,2306.75,0.4258
67.3641,-754.613,2299.07,0.4258
67.3941,-754.613,2291.38,0.4256
67.4241,-754.614,2283.66,0.4254
67.4541,-754.614,2275.93,0.4252
67.4841,-754.615,2268.07,0.4252
67.5141,-754.615,2260.34,0.425
67.5441,-754.616,2252.6,0.4248
67.5741,-754.616,2244.9,0.4246
67.6041,-754.617,2237.26,0.4244
67.6341,-754.617,2229.48,0.4244
67.6641,-754.618,2221.76,0.4242
67.6941,-754.618,2213.94,0.424
67.7241,-754.619,2206.17,0.4238
67.7541,-754.619,2198.35,0.4238
67.7841,-754.62,2190.49,0.4236
67.8141,-754.62,2182.69,0.4234
67.8441,-754.621,2174.83,0.4234
67.8741,-754.621,2167,0.4232
67.9041,-754.622,2159.23,0.423
67.9341,-754.622,2151.38,0.4228
67.9641,-754.623,2143.64,0.4226
67.9941,-754.623,2135.93,0.42241
68.0241,-754.624,2128.29,0.4224
68.0541,-754.624,2120.66,0.4222
68.0841,-754.625,2113,0.422
68.1141,-754.625,2105.37,0.422
68.1441,-754.626,2097.73,0.4218
68.1741,-754.626,2090.11,0.4216
68.2041,-754.627,2082.49,0.4214
68.2341,-754.627,2074.92,0.4214
68.2641,-754.628,2067.35,0.4212
68.2941,-754.628,2059.76,0.421
68.3241,-754.629,2052.1,0.4208
68.3541,-754.629,2044.43,0.4206
68.3841,-754.63,2036.74,0.4206
68.4141,-754.63,2029.04,0.4204
68.4441,-754.631,2021.36,0.4202
68.4741,-754.631,2013.62,0.42
68.5041,-754.632,2005.94,0.42
68.5341,-754.632,1998.24,0.4198
68.5641,-754.633,1990.5,0.4196
68.5941,-754.633,1982.8,0.4194
68.6241,-754.634,1975.1,0.4192
68.6541,-754.634,1967.46,0.4192
68.6841,-754.635,1959.77,0.419
68.7141,-754.635,1952.16,0.4188
68.7441,-754.636,1944.59,0.4186
68.7741,-754.636,1937.04,0.41841
68.8041,-754.637,1929.55,0.4184
68.8341,-754.637,1922.04,0.4182
68.8641,-754.638,1914.49,0.418
68.8941,-754.638,1906.98,0.4178
68.9241,-754.639,1899.45,0.4178
68.9541,-754.639,1891.93,0.4176
68.9841,-754.64,1884.39,0.4174
69.0141,-754.64,1876.86,0.4172
69.0441,-754.641,1869.34,0.417
69.0741,-754.641,1861.79,0.417
69.1041,-754.642,1854.22,0.4168
69.1341,-754.642,1846.68,0.4166
69.1641,-754.643,1839.16,0.4164
69.1941,-754.643,1831.7,0.4162
69.2241,-754.644,1824.2,0.4162
69.2541,-754.644,1816.69,0.416
69.2841,-754.645,1809.05,0.4158
69.3141,-754.645,1801.45,0.4156
69.3441,-754.646,1793.83,0.4154
69.3741,-754.646,1786.24,0.4154
69.4041,-754.647,1778.7,0.4152
69.4341,-754.647,1771.09,0.415
69.4641,-754.648,1763.55,0.4148
69.4941,-754.648,1756.11,0.4146
69.5241,-754.649,1748.77,0.4146
69.5541,-754.649,1741.46,0.4144
69.5841,-754.65,1734.16,0.4142
69.6141,-754.65,1726.81,0.414
69.6441,-754.651,1719.5,0.414
69.6741,-754.651,1712.18,0.4138
69.7041,-754.652,1704.85,0.4136
69.7341,-754.652,1697.46,0.4134
69.7641,-754.653,1690.1,0.4132
69.7941,-754.653,1682.65,0.4132
69.8241,-754.654,1675.29,0.413
69.8541,-754.654,1667.93,0.4128
69.8841,-754.655,1660.61,0.4126
69.9141,-754.655,1653.23,0.4124
69.9441,-754.656,1645.81,0.4122
69.9741,-754.656,1638.39,0.4122
70.0041,-754.657,1630.89,0.412
70.0341,-754.657,1623.44,0.4118
70.0641,-754.658,1616.02,0.4116
70.0941,-754.658,1608.57,0.4114
70.1241,-754.659,1601.08,0.41121
70.1541,-754.659,1593.63,0.4112
70.1841,-754.66,1586.24,0.411
70.2141,-754.66,1578.89,0.4108
70.2441,-754.661,1571.53,0.4106
70.2741,-754.661,1564.24,0.4104
70.3041,-754.662,1557.03,0.4104
70.3341,-754.662,1549.8,0.4102
70.3641,-754.663,1542.65,0.41
70.3941,-754.663,1535.51,0.4098
70.4241,-754.664,1528.39,0.4096
70.4541,-754.664,1521.23,0.4094
70.4841,-754.665,1514,0.4094
70.5141,-754.665,1506.71,0.4092
70.5441,-754.666,1499.45,0.409
70.5741,-754.666,1492.19,0.4088
70.6041,-754.667,1485.03,0.4086
70.6341,-754.667,1477.85,0.40841
70.6641,-754.668,1470.69,0.4084
70.6941,-754.668,1463.48,0.4082
70.7241,-754.669,1456.31,0.408
70.7541,-754.669,1449.08,0.4078
70.7841,-754.67,1441.9,0.4076
70.8141,-754.67,1434.78,0.4074
70.8441,-754.671,1427.63,0.4074
70.8741,-754.671,1420.46,0.4072
70.9041,-754.672,1413.2,0.407
70.9341,-754.672,1405.98,0.4068
70.9641,-754.673,1398.75,0.4066
70.9941,-754.673,1391.59,0.4064
71.0241,-754.674,1384.46,0.40621
71.0541,-754.674,1377.33,0.4062
71.0841,-754.675,1370.38,0.406
71.1141,-754.675,1363.37,0.4058
71.1441,-754.676,1356.54,0.4056
71.1741,-754.676,1349.61,0.4054
71.2041,-754.677,1342.7,0.4052
71.2341,-754.677,1335.73,0.4052
71.2641,-754.678,1328.71,0.405
71.2941,-754.678,1321.64,0.4048
71.3241,-754.679,1314.61,0.4046
71.3541,-754.679,1307.6,0.4044
71.3841,-754.68,1300.67,0.4042
71.4141,-754.68,1293.73,0.404
71.4441,-754.681,1286.81,0.404
71.4741,-754.681,1279.86,0.4038
71.5041,-754.682,1272.86,0.4036
71.5341,-754.682,1265.86,0.4034
71.5641,-754.683,1258.92,0.4032
71.5941,-754.683,1251.95,0.403
71.6241,-754.684,1244.98,0.4028
71.6541,-754.684,1237.97,0.4026
71.6841,-754.685,1230.95,0.4026
71.7141,-754.685,1224,0.4024
71.7441,-754.686,1217.12,0.4022
71.7741,-754.686,1210.27,0.402
71.8041,-754.687,1203.49,0.4018
71.8341,-754.687,1196.75,0.4016
71.8641,-754.688,1190.06,0.4016
71.8941,-754.688,1183.4,0.4014
71.9241,-754.689,1176.72,0.4012
71.9541,-754.689,1170.02,0.401
71.9841,-754.69,1163.29,0.4008
72.0141,-754.69,1156.55,0.4006
72.0441,-754.691,1149.78,0.4004
72.0741,-754.691,1143.01,0.4004
72.1041,-754.692,1136.22,0.4002
72.1341,-754.692,1129.52,0.4
72.1641,-754.693,1122.85,0.3998
72.1941,-754.693,1116.23,0.3996
72.2241,-754.694,1109.65,0.3994
72.2541,-754.694,1103.05,0.3992
72.2841,-754.695,1096.41,0.399
72.3141,-754.695,1089.7,0.399
72.3441,-754.696,1082.96,0.3988
72.3741,-754.696,1076.19,0.3986
72.4041,-754.697,1069.35,0.3984
72.4341,-754.697,1062.53,0.3982
72.4641,-754.698,1055.76,0.398
72.4941,-754.698,1049.11,0.3978
72.5241,-754.699,1042.53,0.3976
72.5541,-754.699,1035.95,0.3974
72.5841,-754.7,1029.4,0.3972
72.6141,-754.7,1022.91,0.39701
72.6441,-754.701,1016.39,0.397
72.6741,-754.701,1009.95,0.3968
72.7041,-754.702,1003.42,0.3966
72.7341,-754.702,996.874,0.3964
72.7641,-754.703,990.339,0.3962
72.7941,-754.703,983.844,0.396
72.8241,-754.704,977.344,0.3958
72.8541,-754.704,970.872,0.3956
72.8841,-754.705,964.328,0.3954
72.9141,-754.705,957.934,0.3954
72.9441,-754.706,951.439,0.3952
72.9741,-754.706,945.049,0.395
73.0041,-754.707,938.585,0.3948
73.0341,-754.707,932.095,0.3946
73.0641,-754.708,925.68,0.3944
73.0941,-754.708,919.256,0.3942
73.1241,-754.709,912.775,0.394
73.1541,-754.709,906.272,0.3938
73.1841,-754.71,899.72,0.39361
73.2141,-754.71,893.296,0.3936
73.2441,-754.711,886.922,0.3934
73.2741,-754.711,880.572,0.3932
73.3041,-754.712,874.298,0.393
73.3341,-754.712,867.998,0.3928
73.3641,-754.713,861.8,0.3926
73.3941,-754.713,855.574,0.3924
73.4241,-754.714,849.394,0.3922
73.4541,-754.714,843.212,0.39201
73.4841,-754.715,837.079,0.392
73.5141,-754.715,830.928,0.3918
73.5441,-754.716,824.708,0.3916
73.5741,-754.716,818.51,0.3914
73.6041,-754.717,812.325,0.3912
73.6341,-754.717,806.131,0.391
73.6641,-754.718,799.914,0.3908
73.6941,-754.718,793.835,0.3906
73.7241,-754.719,787.799,0.3906
73.7541,-754.719,781.727,0.3904
73.7841,-754.72,775.675,0.3902
73.8141,-754.72,769.528,0.39
73.8441,-754.721,763.394,0.3898
73.8741,-754.721,757.257,0.3896
73.9041,-754.722,751.075,0.3894
73.9341,-754.722,744.937,0.3892
73.9641,-754.723,738.791,0.389
73.9941,-754.723,732.717,0.389
74.0241,-754.724,726.733,0.3888
74.0541,-754.724,720.814,0.3886
74.0841,-754.725,714.873,0.3884
74.1141,-754.725,708.977,0.3882
74.1441,-754.726,703.146,0.388
74.1741,-754.726,697.323,0.3878
74.2041,-754.727,691.578,0.3876
74.2341,-754.727,685.821,0.3876
74.2641,-754.728,680.081,0.3874
74.2941,-754.728,674.326,0.3872
74.3241,-754.729,668.633,0.387
74.3541,-754.729,662.826,0.3868
74.3841,-754.73,657.098,0.3866
74.4141,-754.73,651.369,0.3864
74.4441,-754.731,645.673,0.3864
74.4741,-754.731,639.93,0.3862
74.5041,-754.732,634.226,0.386
74.5341,-754.732,628.477,0.3858
74.5641,-754.733,622.791,0.3856
74.5941,-754.733,617.01,0.3854
74.6241,-754.734,611.301,0.3852
74.6541,-754.734,605.603,0.3852
74.6841,-754.735,599.908,0.385
74.7141,-754.735,594.242,0.3848
74.7441,-754.736,588.494,0.3846
74.7741,-754.736,582.769,0.3844
74.8041,-754.737,577.03,0.3842
74.8341,-754.737,571.456,0.384
74.8641,-754.738,565.911,0.384
74.8941,-754.738,560.383,0.3838
74.9241,-754.739,554.889,0.3836
74.9541,-754.739,549.481,0.3834
74.9841,-754.74,544.071,0.3832
75.0141,-754.74,538.605,0.383
75.0441,-754.741,533.094,0.383
75.0741,-754.741,527.567,0.3828
75.1041,-754.742,522.084,0.3826
75.1341,-754.742,516.573,0.3824
75.1641,-754.743,511.081,0.3822
75.1941,-754.743,505.522,0.3822
75.2241,-754.744,500.025,0.382
75.2541,-754.744,494.502,0.38179
75.2841,-754.745,489.041,0.3814
75.3141,-754.745,483.572,0.3812
75.3441,-754.746,478.023,0.3812
75.3741,-754.746,472.524,0.381
75.4041,-754.747,467.02,0.381
75.4341,-754.747,461.49,0.3808
75.4641,-754.748,456.033,0.38059
75.4941,-754.748,450.498,0.3802
75.5241,-754.749,444.992,0.38
75.5541,-754.749,439.536,0.38
75.5841,-754.75,434.079,0.3798
75.6141,-754.75,428.611,0.3796
75.6441,-754.751,423.208,0.3794
75.6741,-754.751,417.909,0.3792
75.7041,-754.752,412.658,0.3792
75.7341,-754.752,407.334,0.379
75.7641,-754.753,401.973,0.3788
75.7941,-754.753,396.613,0.3786
75.8241,-754.754,391.267,0.3784
75.8541,-754.754,385.924,0.3782
75.8841,-754.755,380.561,0.378
75.9141,-754.755,375.184,0.37781
75.9441,-754.756,369.819,0.37761
75.9741,-754.756,364.475,0.3776
76.0041,-754.757,359.157,0.3774
76.0341,-754.757,353.857,0.3772
76.0641,-754.758,348.523,0.377
76.0941,-754.758,343.227,0.3768
76.1241,-754.759,337.865,0.3766
76.1541,-754.759,332.496,0.3766
76.1841,-754.76,327.098,0.3764
76.2141,-754.76,321.655,0.376
76.2441,-754.761,316.333,0.3758
76.2741,-754.761,311,0.37561
76.3041,-754.762,305.771,0.3756
76.3341,-754.762,300.56,0.3754
76.3641,-754.763,295.349,0.3752
76.3941,-754.763,290.154,0.375
76.4241,-754.764,284.901,0.3748
76.4541,-754.764,279.751,0.3746
76.4841,-754.765,274.64,0.37441
76.5141,-754.765,269.528,0.3744
76.5441,-754.766,264.447,0.3742
76.5741,-754.766,259.316,0.374
76.6041,-754.767,254.186,0.3738
76.6341,-754.767,248.962,0.3736
76.6641,-754.768,243.775,0.3734
76.6941,-754.768,238.621,0.3732
76.7241,-754.769,233.548,0.373
76.7541,-754.769,228.527,0.3728
76.7841,-754.77,223.423,0.3726
76.8141,-754.77,218.351,0.3724
76.8441,-754.771,213.158,0.3724
76.8741,-754.771,208.021,0.3722
76.9041,-754.772,202.902,0.372
76.9341,-754.772,197.78,0.3718
76.9641,-754.773,192.634,0.3716
76.9941,-754.773,187.432,0.3714
77.0241,-754.774,182.264,0.3712
77.0541,-754.774,177.045,0.371
77.0841,-754.775,171.955,0.3708
77.1141,-754.775,167.051,0.3706
77.1441,-754.776,162.184,0.3704
77.1741,-754.776,157.304,0.3702